Workbook

Sheet INDEX
C1: INDEX | F1: Company
C4: Sr No. | D4: Particulars | E4: Link to Sheet
C5: 1 | D5: Balance Sheet | E5: Balance Sheet
C6: 2 | D6: Profit & Loss | E6: Profit and Loss Statement
C7: 3 | D7: Cash Flow Statement | E7: Cash Flow Statement
C8: 4 | D8: Share Holding Pattern | E8: Share Holding Pattern
C9: 5 | D9: Calculation of Financial Ratio | E9: Financial ratio
C10: 6 | D10: Du Pont Analysis | E10: Du Pont Analysis
C11: 7 | D11: Calculation of Market return | E11: Market Return
C12: 8 | D12: Beta calculation using Historical return | E12: Beta Calculation using HR
C13: 9 | D13: Bottom up Beta Calculation | E13: Bottom Up Beta using peers
C14: 10 | D14: Calculation of Ke | E14: COE using CAPM
C15: 11 | D15: Calculation of Kd | E15: COD using Default Spread
C16: 12 | D16: WACC | E16: WACC
... C20: 16 | D20: References | E20: References

Sheet Balance Sheet
C2: 41699 | D2: 42064 | E2: 42430 | F2: 42795 | G2: 43160 | H2: 43525 | I2: 43891 | J2: 44256 | K2: 44621 | L2: 44986 | M2: 45352 | N2: 45717
B3: Equity Capital | C3: 237 | D3: 270 | E3: 270 | F3: 270 | G3: 270 | H3: 270 | I3: 270 | J3: 320 | K3: 320 | L3: 320 | M3: 320 | N3: 320
B4: Reserves | C4: 12890 | D4: 15458 | E4: 15080 | F4: 16321 | G4: 12718 | H4: 15419 | I4: 14991 | J4: 9559 | K4: 10560 | L4: 13380 | M4: 15468 | N4: 18046
B5: Borrowings - | C5: 11080 | D5: 11037 | E5: 11229 | F5: 16504 | G5: 16571 | H5: 17453 | I5: 18081 | J5: 27210 | K5: 27567 | L5: 24920 | M5: 22613 | N5: 20066
B6: Long term Borrowings | C6: 7176 | D6: 8796 | E6: 8984 | F6: 8848 | G6: 8124 | H6: 8750 | I6: 9825 | J6: 16583 | K6: 18088 | L6: 11272 | M6: 13373 | N6: 12613
B7: Short term Borrowings | C7: 1580 | D7: 1765 | E7: 1507 | F7: 2392 | G7: 4326 | H7: 6732 | I7: 6212 | J7: 7878 | K7: 6620 | L7: 10593 | M7: 6153 | N7: 4359
B8: Lease Liabilities | C8: 0 | D8: 0 | E8: 0 | F8: 0 | G8: 0 | H8: 0 | I8: 279 | J8: 2749 | K8: 2859 | L8: 3054 | M8: 3086 | N8: 3094
B9: Other Borrowings | C9: 2325 | D9: 477 | E9: 738 | F9: 5264 | G9: 4121 | H9: 1971 | I9: 1764 | J9: 0 | K9: 0 | L9: 0 | M9: 0 | N9: 0
B10: Other Liabilities - | C10: 6331 | D10: 6796 | E10: 8035 | F10: 7737 | G10: 6942 | H10: 4992 | I10: 4274 | J10: 7367 | K10: 8706 | L10: 9553 | M10: 12089 | N10: 14213
B11: Trade Payables | C11: 1058 | D11: 1305 | E11: 1263 | F11: 1346 | G11: 1106 | H11: 1102 | I11: 1002 | J11: 3282 | K11: 4080 | L11: 1985 | M11: 6485 | N11: 8118
B12: Advance from Customers | C12: 449 | D12: 244 | E12: 121 | F12: 158 | G12: 213 | H12: 117 | I12: 150 | J12: 178 | K12: 152 | L12: 191 | M12: 140 | N12: 160
B13: Other liability items | C13: 4825 | D13: 5248 | E13: 6651 | F13: 6232 | G13: 5624 | H13: 3773 | I13: 3122 | J13: 3907 | K13: 4474 | L13: 7377 | M13: 5465 | N13: 5936
B14: Total Liabilities | C14: 30539 | D14: 33561 | E14: 34615 | F14: 40832 | G14: 36502 | H14: 38135 | I14: 37616 | J14: 44456 | K14: 47153 | L14: 48173 | M14: 50489 | N14: 52645
... B34: Other asset items | C34: 6014 | D34: 7340 | E34: 9372 | F34: 6581 | G34: 7624 | H34: 6593 | I34: 5191 | J34: 4765 | K34: 6818 | L34: 6226 | M34: 7196 | N34: 7012
B35: Average Trade Recivable | C35: =C31 -> 1320 | D35: =(D31+C31)/2 -> 1448 | E35: =(E31+D31)/2 -> 1316.5 | F35: =(F31+E31)/2 -> 1146 | G35: =(G31+F31)/2 -> 1103.5 | H35: =(H31+G31)/2 -> 1114 | I35: =(I31+H31)/2 -> 1182.5 | J35: =(J31+I31)/2 -> 1344.5 | K35: =(K31+J31)/2 -> 1303.5 | ... N35: =(N31+M31)/2 -> 1548
B36: Total Assets | C36: 30539 | D36: 33561 | E36: 34615 | F36: 40832 | G36: 36502 | H36: 38135 | I36: 37616 | J36: 44456 | K36: 47153 | L36: 48173 | M36: 50489 | N36: 52645
B37: Average Total Asset | C37: =C36 -> 30539 | D37: =(D36+C36)/2 -> 32050 | E37: =(E36+D36)/2 -> 34088 | F37: =(F36+E36)/2 -> 37723.5 | G37: =(G36+F36)/2 -> 38667 | H37: =(H36+G36)/2 -> 37318.5 | I37: =(I36+H36)/2 -> 37875.5 | J37: =(J36+I36)/2 -> 41036 | K37: =(K36+J36)/2 -> 45804.5 | ... N37: =(N36+M36)/2 -> 51567
B38: Average Inventory | C38: =C30 -> 711 | D38: =(D30+C30)/2 -> 690 | E38: =(E30+D30)/2 -> 679 | F38: =(F30+E30)/2 -> 680 | G38: =(G30+F30)/2 -> 572.5 | H38: =(H30+G30)/2 -> 527 | I38: =(I30+H30)/2 -> 607.5 | J38: =(J30+I30)/2 -> 908 | K38: =(K30+J30)/2 -> 1736.5 | ... N38: =(N30+M30)/2 -> 2272

Sheet Profit and Loss Statement
C2: 41699 | D2: 42064 | E2: 42430 | F2: 42795 | G2: 43160 | H2: 43525 | I2: 43891 | J2: 44256 | K2: 44621 | L2: 44986 | M2: 45352 | N2: 45717
B3: Sales - | C3: 8630 | D3: 8208 | E3: 8691 | F3: 6924 | G3: 7537 | H3: 8255 | I3: 7726 | J3: 13169 | K3: 11108 | L3: 17728 | M3: 20093 | N3: 22359
B4: Sales Growth % | C4: -0.098 | D4: -0.049 | E4: 0.0588 | F4: -0.2033 | G4: 0.0884 | H4: 0.0954 | I4: -0.0641 | J4: 0.7045 | K4: -0.1565 | L4: 0.596 | M4: 0.1334 | N4: 0.1128
B5: Expenses - | C5: 6340 | D5: 6521 | E5: 5730 | F5: 4947 | G5: 5261 | H5: 7563 | I5: 5618 | J5: 10190 | K5: 9470 | L5: 15031 | M5: 16200 | N5: 17959
B6: Manufacturing Cost % | C6: 0.6 | D6: 0.67 | E6: 0.53 | F6: 0.53 | G6: 0.54 | H6: 0.53 | I6: 0.51 | J6: 0.71 | K6: 0.76 | L6: 0.82 | M6: 0.74 | N6: 0.69
B7: Employee Cost % | C7: 0.07 | D7: 0.09 | E7: 0.09 | F7: 0.1 | G7: 0.09 | H7: 0.08 | I7: 0.08 | J7: 0.06 | K7: 0.07 | L7: 0.04 | M7: 0.04 | N7: 0.04
B8: Other Cost % | C8: 0.06 | D8: 0.03 | E8: 0.04 | F8: 0.09 | G8: 0.07 | H8: 0.3 | I8: 0.13 | J8: 0 | K8: 0.03 | L8: -0.02 | M8: 0.02 | N8: 0.08
B9: Operating Profit | C9: 2291 | D9: 1686 | E9: 2961 | F9: 1977 | G9: 2276 | H9: 692 | I9: 2108 | J9: 2980 | K9: 1638 | L9: 2697 | M9: 3894 | N9: 4401
B10: OPM % | C10: 0.27 | D10: 0.21 | E10: 0.34 | F10: 0.29 | G10: 0.3 | H10: 0.08 | I10: 0.27 | J10: 0.23 | K10: 0.15 | L10: 0.15 | M10: 0.19 | N10: 0.2
B11: Other Income - | C11: 656 | D11: 1452 | E11: 524 | F11: 465 | G11: -3497 | H11: 3662 | I11: 28 | J11: 1146 | K11: 3975 | L11: 4808 | M11: 2063 | N11: 2504
B12: Exceptional items | C12: 20 | D12: 23 | E12: -334 | F12: -609 | G12: -4427 | H12: 1560 | I12: -528 | J12: -73 | K12: 985 | L12: 729 | M12: 69 | N12: 40
B13: Other income normal | C13: 635 | D13: 1429 | E13: 857 | F13: 1075 | G13: 929 | H13: 2102 | I13: 557 | J13: 1219 | K13: 2989 | L13: 4080 | M13: 1994 | N13: 2464
B14: Interest | C14: 868 | D14: 1047 | E14: 1146 | F14: 1319 | G14: 1431 | H14: 1500 | I14: 1510 | J14: 2497 | K14: 2189 | L14: 2227 | M14: 2257 | N14: 2095
... B24: Dividend Payout % | C24: 0.31 | D24: 0.35 | E24: 0.26 | F24: 0.88 | G24: -0.11 | H24: 0.2 | I24: 2.83 | J24: 1.69 | K24: 0.2 | L24: 0.2 | M24: 0.29 | N24: 0.26

Sheet Cash Flow Statement
C2: 41699 | D2: 42064 | E2: 42430 | F2: 42795 | G2: 43160 | H2: 43525 | I2: 43891 | J2: 44256 | K2: 44621 | L2: 44986 | M2: 45352 | N2: 45717
B3: Cash from Operating Activity - | C3: 2700 | D3: 1688 | E3: 2947 | F3: 2121 | G3: 2767 | H3: 1683 | I3: 2309 | J3: 3334 | K3: 1684 | L3: 500 | M3: 5881 | N3: 6288
B4: Profit from operations | C4: 2537 | D4: 2207 | E4: 2689 | F4: 2299 | G4: 2323 | H4: 2632 | I4: 1704 | J4: 3025 | K4: 1774 | L4: 2766 | M4: 4166 | N4: 4753
B5: Receivables | C5: -9 | D5: -254 | E5: 499 | F5: -196 | G5: -48 | H5: -251 | I5: -10 | J5: -111 | K5: 630 | L5: -852 | M5: 313 | N5: -882
B6: Inventory | C6: 50 | D6: 41 | E6: -20 | F6: 18 | G6: 95 | H6: -107 | I6: -35 | J6: 2 | K6: -1090 | L6: -144 | M6: 369 | N6: -297
B7: Payables | C7: 134 | D7: 247 | E7: -38 | F7: 83 | G7: -119 | H7: -35 | I7: -278 | J7: 164 | K7: 811 | L7: -2046 | M7: 2157 | N7: 1610
B8: Loans Advances | C8: -182 | D8: 31 | E8: 0 | F8: 0 | G8: 11 | H8: 4 | I8: 7 | J8: 1 | K8: 1 | L8: 0 | M8: 1 | N8: 0
B9: Other WC items | C9: 460 | D9: -287 | E9: -43 | F9: 132 | G9: 680 | H9: -458 | I9: 994 | J9: 333 | K9: -326 | L9: 903 | M9: -1297 | N9: 920
B10: Working capital changes | C10: 453 | D10: -221 | E10: 399 | F10: 37 | G10: 618 | H10: -848 | I10: 679 | J10: 389 | K10: 26 | L10: -2140 | M10: 1543 | N10: 1352
B11: Direct taxes | C11: -291 | D11: -298 | E11: -141 | F11: -216 | G11: -174 | H11: -101 | I11: -74 | J11: -80 | K11: -116 | L11: -126 | M11: 173 | N11: 184
B12: Cash from Investing Activity - | C12: -2343 | D12: -1625 | E12: -1627 | F12: -5582 | G12: -1355 | H12: -557 | I12: -471 | J12: -1174 | K12: 1587 | L12: 5124 | M12: -92 | N12: -71
B13: Fixed assets purchased | C13: -1101 | D13: -1256 | E13: -1009 | F13: -884 | G13: -665 | H13: -522 | I13: -705 | J13: -1061 | K13: -1186 | L13: -1711 | M13: -1659 | N13: -1624
B14: Fixed assets sold | C14: 3 | D14: 28 | E14: 65 | F14: 9 | G14: 16 | H14: 32 | I14: 27 | J14: 258 | K14: 18 | L14: 10 | M14: 136 | N14: 219
... B34: Net Cash Flow | C34: -346 | D34: 211 | E34: -381 | F34: 257 | G34: -192 | H34: 131 | I34: 85 | J34: -458 | K34: -364 | L34: 274 | M34: 325 | N34: 912

Sheet Share Holding Pattern 
B2: Promoters - | C2: 0.3302 | D2: 0.3302 | E2: 0.33 | F2: 0.3722 | G2: 0.4686 | H2: 0.4686 | I2: 0.4686 | J2: 0.4686 | K2: 0.4686
B3: Tata Sons Private Limited | C3: 31.05 | D3: 31.05 | E3: 31.05 | F3: 35.27 | G3: 45.21 | H3: 45.21 | I3: 45.21 | J3: 45.21 | K3: 45.21 | N3: Here taken as Standalone from Screener
B4: Tata Steel Limited | C4: 1.45 | D4: 1.45 | E4: 1.45 | F4: 1.45 | G4: 1.22 | H4: 1.22 | I4: 1.22 | J4: 1.22 | K4: 1.22
B5: Tata Investment Corporation Ltd | C5: 0.25 | D5: 0.25 | E5: 0.25 | F5: 0.25 | G5: 0.21 | H5: 0.21 | I5: 0.21 | J5: 0.21 | K5: 0.21
B6: Tata Industries Limited | C6: 0.17 | D6: 0.17 | E6: 0.17 | F6: 0.17 | G6: 0.14 | H6: 0.14 | I6: 0.14 | J6: 0.14 | K6: 0.14
B7: Ewart Investments Limited | C7: 0.08 | D7: 0.08 | E7: 0.08 | F7: 0.08 | G7: 0.07 | H7: 0.07 | I7: 0.07 | J7: 0.07 | K7: 0.07
B8: Sir Dorabji Tata Trust | C8: 0.02 | D8: 0.02 | E8: 0
B9: Sir Ratan Tata Trust | C9: 0 | D9: 0 | E9: 0
B10: Sir Dorabji Tata Trust (R N Tata)(V Srinivasan)(V ... | F10: 0 | G10: 0 | H10: 0
B11: Sheba Properties Ltd | C11: 0
B12: Tata Motors Finance Limited | D12: 0 | E12: 0 | F12: 0 | G12: 0 | H12: 0 | I12: 0
B13: J R D Tata Trust | C13: 0 | E13: 0
B14: J R D Trust | D14: 0
B15: Sir Ratan Tata Trust (R N Tata)(V Srinivasan)(V Si... | F15: 0 | G15: 0 | H15: 0
B16: JRD Tata Trust (R N Tata)(V Srinivasan)(V Singh) | F16: 0 | G16: 0 | H16: 0
B17: Sir Dorabji Tata Trust | I17: 0
B18: (Mr. R.N. Tata)
B19: (Mr. V. Si...
B20: Sir Ratan Tata Trust | I20: 0
B21: (Mr. R.N. Tata)
B22: (Mr. V. Singh...
B23: JRD Tata Trust | I23: 0 | J23: 0
B24: (Mr. R. N. Tata)
B25: (Mr. Vijay Singh)
B26: ...
B27: Tata Motors Finance Limited | J27: 0 | K27: 0
B28: (Formerly Tata Motors...
B29: TMF Business Services Limited | J29: 0 | K29: 0
B30: (Formerly Tata Moto...
B31: Sir Ratan Tata Trust | J31: 0
B32: (Mr. R. N. Tata)
B33: (Mr. Vijay S...
B34: Sir Dorabji Tata Trust | J34: 0
B35: (Mr. R. N. Tata)
B36: (Mr. Vija...
B37: SIR DORABJI TATA TRUST | K37: 0
B38: (Mr. Noel N. Tata)
B39: (Mr. V...
B40: SIR RATAN TATA TRUST | K40: 0
B41: (Mr. Noel N. Tata)
...

Sheet Financial ratio 
C1: 41699 | D1: 42064 | E1: 42430 | F1: 42795 | G1: 43160 | H1: 43525 | I1: 43891 | J1: 44256 | K1: 44621 | L1: 44986 | M1: 45352 | N1: 45717 | O1: Ideal Value | P1: Formulas | Q1: Average | R1: Analysis | T1: Ideal value is the median of all ratio values of the power industry.
B2: Profitability Ratios
B3: Net Profit Ratio | C3: ='Profit and Loss Statement'!C18/'Profit and Loss Statement'!C3 -> 0.11054461 | D3: ='Profit and Loss Statement'!D18/'Profit and Loss Statement'!D3 -> 0.12305068 | E3: ='Profit and Loss Statement'!E18/'Profit and Loss Statement'!E3 -> 0.15590841 | F3: ='Profit and Loss Statement'!F18/'Profit and Loss Statement'!F3 -> 0.057481225 | G3: ='Profit and Loss Statement'!G18/'Profit and Loss Statement'!G3 -> -0.41807085 | H3: ='Profit and Loss Statement'!H18/'Profit and Loss Statement'!H3 -> 0.21429437 | I3: ='Profit and Loss Statement'!I18/'Profit and Loss Statement'!I3 -> 0.019156096 | J3: ='Profit and Loss Statement'!J18/'Profit and Loss Statement'!J3 -> 0.022325158 | ... N3: ='Profit and Loss Statement'!N18/'Profit and Loss Statement'!N3 -> 0.14012255 | O3: 13.72 | P3: Net Profit / Sales | Q3: =AVERAGE(C3:N3) -> 0.08088979 | R3: Volatile trend with sharp dips (FY18) and surges post-FY22; mostly outperforms average (8.09%) and meets/exceeds ideal (13.72%) in recent years.
C4: Good | D4: Good | E4: Excellent | F4: Good | G4: Bad | H4: Excellent | I4: Bad | J4: Bad | K4: Excellent | L4: Excellent | M4: Good | N4: Excellent
B5: Operating Margin | C5: ='Profit and Loss Statement'!C10 -> 0.27 | D5: ='Profit and Loss Statement'!D10 -> 0.21 | E5: ='Profit and Loss Statement'!E10 -> 0.34 | F5: ='Profit and Loss Statement'!F10 -> 0.29 | G5: ='Profit and Loss Statement'!G10 -> 0.3 | H5: ='Profit and Loss Statement'!H10 -> 0.08 | I5: ='Profit and Loss Statement'!I10 -> 0.27 | J5: ='Profit and Loss Statement'!J10 -> 0.23 | ... N5: ='Profit and Loss Statement'!N10 -> 0.2 | O5: 0.2973 | P5: - | Q5: =AVERAGE(C5:N5) -> 0.22333333 | R5: Generally strong margins close to ideal (30%) except dips in FY19 and FY22; average (22.33%) met or exceeded in most years.
C6: Good | D6: Good | E6: Excellent | F6: Good | G6: Good | H6: Bad | I6: Good | J6: Good | K6: Bad | L6: Bad | M6: Good | N6: Good
B7: Return on Assets | C7: ='Profit and Loss Statement'!C18/'Balance Sheet'!C36 -> 0.031238744 | D7: ='Profit and Loss Statement'!D18/'Balance Sheet'!D36 -> 0.030094455 | E7: ='Profit and Loss Statement'!E18/'Balance Sheet'!E36 -> 0.039144879 | F7: ='Profit and Loss Statement'!F18/'Balance Sheet'!F36 -> 0.0097472571 | G7: ='Profit and Loss Statement'!G18/'Balance Sheet'!G36 -> -0.086324037 | H7: ='Profit and Loss Statement'!H18/'Balance Sheet'!H36 -> 0.046387833 | I7: ='Profit and Loss Statement'!I18/'Balance Sheet'!I36 -> 0.003934496 | J7: ='Profit and Loss Statement'!J18/'Balance Sheet'!J36 -> 0.0066132805 | ... N7: ='Profit and Loss Statement'!N18/'Balance Sheet'!N36 -> 0.059511824 | O7: 0.0262 | P7: Net Profit / Total Assets | Q7: =AVERAGE(C7:N7) -> 0.02594802 | R7: Fluctuating trend but performance improved post-FY22; beat both ideal (2.62%) and average (2.59%) recently, showing better asset utilization.
C8: Good | D8: Good | E8: Good | F8: Bad | G8: Bad | H8: Good | I8: Bad | J8: Bad | K8: Excellent | L8: Excellent | M8: Good | N8: Excellent
B9: Return on Capital Employed | C9: ='Profit and Loss Statement'!C9/('Balance Sheet'!C4+'Balance Sheet'!C3+'Balance Sheet'!C5) -> 0.094642046 | D9: ='Profit and Loss Statement'!D9/('Balance Sheet'!D4+'Balance Sheet'!D3+'Balance Sheet'!D5) -> 0.062992714 | E9: ='Profit and Loss Statement'!E9/('Balance Sheet'!E4+'Balance Sheet'!E3+'Balance Sheet'!E5) -> 0.11140374 | F9: ='Profit and Loss Statement'!F9/('Balance Sheet'!F4+'Balance Sheet'!F3+'Balance Sheet'!F5) -> 0.05973712 | G9: ='Profit and Loss Statement'!G9/('Balance Sheet'!G4+'Balance Sheet'!G3+'Balance Sheet'!G5) -> 0.076998545 | H9: ='Profit and Loss Statement'!H9/('Balance Sheet'!H4+'Balance Sheet'!H3+'Balance Sheet'!H5) -> 0.02087985 | I9: ='Profit and Loss Statement'!I9/('Balance Sheet'!I4+'Balance Sheet'!I3+'Balance Sheet'!I5) -> 0.063223562 | J9: ='Profit and Loss Statement'!J9/('Balance Sheet'!J4+'Balance Sheet'!J3+'Balance Sheet'!J5) -> 0.080347273 | ... N9: ='Profit and Loss Statement'!N9/('Balance Sheet'!N4+'Balance Sheet'!N3+'Balance Sheet'!N5) -> 0.11451395 | O9: 0.0869 | P9: Operating profit / Capital employed | Q9: =AVERAGE(C9:N9) -> 0.074881733 | R9: Weak and inconsistent returns on capital; only FY16, FY24, and FY25 exceed ideal (8.69%), rest underperform average (7.49%).
C10: Good | D10: Bad | E10: Excellent | F10: Bad | G10: Bad | H10: Bad | I10: Bad | J10: Good | K10: Bad | L10: Bad | M10: Good | N10: Excellent
B11: Return on Equity | C11: ='Profit and Loss Statement'!C18/('Balance Sheet'!C3+'Balance Sheet'!C4) -> 0.07267464 | D11: ='Profit and Loss Statement'!D18/('Balance Sheet'!D3+'Balance Sheet'!D4) -> 0.064216684 | E11: ='Profit and Loss Statement'!E18/('Balance Sheet'!E3+'Balance Sheet'!E4) -> 0.088273616 | F11: ='Profit and Loss Statement'!F18/('Balance Sheet'!F3+'Balance Sheet'!F4) -> 0.02398891 | G11: ='Profit and Loss Statement'!G18/('Balance Sheet'!G3+'Balance Sheet'!G4) -> -0.24260856 | H11: ='Profit and Loss Statement'!H18/('Balance Sheet'!H3+'Balance Sheet'!H4) -> 0.11275416 | I11: ='Profit and Loss Statement'!I18/('Balance Sheet'!I3+'Balance Sheet'!I4) -> 0.0096979228 | J11: ='Profit and Loss Statement'!J18/('Balance Sheet'!J3+'Balance Sheet'!J4) -> 0.029760097 | ... N11: ='Profit and Loss Statement'!N18/('Balance Sheet'!N3+'Balance Sheet'!N4) -> 0.17058695 | O11: 0.0746 | P11: Net Profit / Total Equity | Q11: =AVERAGE(C11:N11) -> 0.080410127 | R11: ROE deteriorated sharply in FY18 but rebounded strongly post-FY22; recent years exceed both ideal (7.46%) and average (8.04%).
C12: Good | D12: Good | E12: Good | F12: Bad | G12: Bad | H12: Good | I12: Bad | J12: Bad | K12: Excellent | L12: Excellent | M12: Excellent | N12: Excellent
B13: Dividend Payout Ratio | C13: ='Profit and Loss Statement'!C24 -> 0.31 | D13: ='Profit and Loss Statement'!D24 -> 0.35 | E13: ='Profit and Loss Statement'!E24 -> 0.26 | F13: ='Profit and Loss Statement'!F24 -> 0.88 | G13: ='Profit and Loss Statement'!G24 -> -0.11 | H13: ='Profit and Loss Statement'!H24 -> 0.2 | I13: ='Profit and Loss Statement'!I24 -> 2.83 | J13: ='Profit and Loss Statement'!J24 -> 1.69 | ... N13: ='Profit and Loss Statement'!N24 -> 0.26 | O13: 0 | P13: - | Q13: =AVERAGE(C13:N13) -> 0.61333333 | R13: Highly erratic dividend policy with multiple years of unsustainable payouts (>100%) and only a few years aligning with the ideal reinvestment-focused range (0–30%).
C14: Good | D14: Bad | E14: Excellent | F14: Bad | G14: Bad | H14: Excellent | I14: Bad | J14: Bad | K14: Excellent | L14: Excellent | M14: Excellent | N14: Excellent
B15: Price to Earnings Ratio | C15: =C17/C11 -> 21.052736 | D15: =D17/D11 -> 20.711129 | E15: =E17/E11 -> 12.914391 | F15: =F17/F11 -> 61.695176 | G15: =G17/G11 -> -6.801079 | H15: =H17/H11 -> 12.505082 | I15: =I17/I11 -> 67.024662 | J15: =J17/J11 -> 65.52398 | ... N15: =N17/N11 -> 38.279598 | O15: 34.8 | P15: (MV/BV)/ROE | Q15: =AVERAGE(C15:N15) -> 32.955017 | R15: Highly volatile and often distorted (negative FY18); oscillates around ideal (34.8), with occasional overvaluation and undervaluation signals.
C16: Good | D16: Good | E16: Excellent | F16: Bad | G16: Bad | H16: Excellent | I16: Bad | J16: Bad | K16: Good | L16: Good | M16: Bad | N16: Good
B17: Market Value/Book Value | C17: 1.53 | D17: 1.33 | E17: 1.14 | F17: 1.48 | G17: 1.65 | H17: 1.41 | I17: 0.65 | J17: 1.95 | K17: 7.02 | L17: 4.44 | M17: 7.98 | N17: 6.53 | O17: 2.41 | P17: - | Q17: =AVERAGE(C17:N17) -> 3.0925 | R17: Improved significantly in recent years, moving from undervaluation to high premiums; mostly exceeds ideal (2.41) post-FY22, signaling strong market confidence.
C18: Good | D18: Good | E18: Bad | F18: Good | G18: Good | H18: Good | I18: Bad | J18: Good | K18: Excellent | L18: Excellent | M18: Excellent | N18: Excellent
B20: Liquidity Ratio
B21: Current Ratio | C21: =(SUM('Balance Sheet'!C30:C34))/SUM('Balance Sheet'!C11:C13) -> 1.3902401 | D21: =(SUM('Balance Sheet'!D30:D34))/SUM('Balance Sheet'!D11:D13) -> 1.4947771 | E21: =(SUM('Balance Sheet'!E30:E34))/SUM('Balance Sheet'!E11:E13) -> 1.4306161 | F21: =(SUM('Balance Sheet'!F30:F34))/SUM('Balance Sheet'!F11:F13) -> 1.149302 | G21: =(SUM('Balance Sheet'!G30:G34))/SUM('Balance Sheet'!G11:G13) -> 1.4004033 | H21: =(SUM('Balance Sheet'!H30:H34))/SUM('Balance Sheet'!H11:H13) -> 1.7676282 | I21: =(SUM('Balance Sheet'!I30:I34))/SUM('Balance Sheet'!I11:I13) -> 1.8322415 | J21: =(SUM('Balance Sheet'!J30:J34))/SUM('Balance Sheet'!J11:J13) -> 1.2801683 | ... N21: =(SUM('Balance Sheet'!N30:N34))/SUM('Balance Sheet'!N11:N13) -> 0.89897284 | O21: 1.27 | P21: current assets / current liabilities | Q21: =AVERAGE(C21:N21) -> 1.3426678 | R21: Strong current ratio, suggesting firm has enough assets to meet its liabilities in the short term. However, a declining trend is observed post 2021.
C22: Good | D22: Good | E22: Good | F22: Good | G22: Good | H22: Excellent | I22: Excellent | J22: Good | K22: Good | L22: Good | M22: Bad | N22: Bad
B23: Quick Ratio | C23: =(SUM('Balance Sheet'!C30:C34)-'Balance Sheet'!C30)/SUM('Balance Sheet'!C11:C13) -> 1.2779533 | D23: =(SUM('Balance Sheet'!D30:D34)-'Balance Sheet'!D30)/SUM('Balance Sheet'!D11:D13) -> 1.3963513 | E23: =(SUM('Balance Sheet'!E30:E34)-'Balance Sheet'!E30)/SUM('Balance Sheet'!E11:E13) -> 1.3448662 | F23: =(SUM('Balance Sheet'!F30:F34)-'Balance Sheet'!F30)/SUM('Balance Sheet'!F11:F13) -> 1.0625646 | G23: =(SUM('Balance Sheet'!G30:G34)-'Balance Sheet'!G30)/SUM('Balance Sheet'!G11:G13) -> 1.3321331 | H23: =(SUM('Balance Sheet'!H30:H34)-'Balance Sheet'!H30)/SUM('Balance Sheet'!H11:H13) -> 1.6514423 | I23: =(SUM('Balance Sheet'!I30:I34)-'Balance Sheet'!I30)/SUM('Balance Sheet'!I11:I13) -> 1.6836687 | J23: =(SUM('Balance Sheet'!J30:J34)-'Balance Sheet'!J30)/SUM('Balance Sheet'!J11:J13) -> 1.1198588 | ... N23: =(SUM('Balance Sheet'!N30:N34)-'Balance Sheet'!N30)/SUM('Balance Sheet'!N11:N13) -> 0.72843675 | O23: 1.08 | P23: (current assets - inventories) / current liabilities | Q23: =AVERAGE(C23:N23) -> 1.1974183 | R23: A similar trend is observed as the Current ratios, remained consistent over the years till FY22, thereafter a decline is observed
C24: Good | D24: Good | E24: Good | F24: Good | G24: Good | H24: Excellent | I24: Excellent | J24: Good | K24: Good | L24: bad | M24: Bad | N24: Bad
B26: Capital Structure Ratio
B27: Debt to Equity Ratio(Total debt/TE) | C27: =('Balance Sheet'!C6+'Balance Sheet'!C7)/('Balance Sheet'!C4+'Balance Sheet'!C3) -> 0.66702217 | D27: =('Balance Sheet'!D6+'Balance Sheet'!D7)/('Balance Sheet'!D4+'Balance Sheet'!D3) -> 0.67147762 | E27: =('Balance Sheet'!E6+'Balance Sheet'!E7)/('Balance Sheet'!E4+'Balance Sheet'!E3) -> 0.68345277 | F27: =('Balance Sheet'!F6+'Balance Sheet'!F7)/('Balance Sheet'!F4+'Balance Sheet'!F3) -> 0.67747574 | G27: =('Balance Sheet'!G6+'Balance Sheet'!G7)/('Balance Sheet'!G4+'Balance Sheet'!G3) -> 0.95857715 | H27: =('Balance Sheet'!H6+'Balance Sheet'!H7)/('Balance Sheet'!H4+'Balance Sheet'!H3) -> 0.98680604 | I27: =('Balance Sheet'!I6+'Balance Sheet'!I7)/('Balance Sheet'!I4+'Balance Sheet'!I3) -> 1.0508486 | J27: =('Balance Sheet'!J6+'Balance Sheet'!J7)/('Balance Sheet'!J4+'Balance Sheet'!J3) -> 2.4760603 | ... N27: =('Balance Sheet'!N6+'Balance Sheet'!N7)/('Balance Sheet'!N4+'Balance Sheet'!N3) -> 0.92409888 | O27: 0.7 | P27: Total debt / total equity | Q27: =AVERAGE(C27:N27) -> 1.1832936 | R27: Optimal Debt/Equity ratio, suggests that firm has enough capacity to meet its debt obligations. However, the ratio has shown a risky trend in the COVID period(probable cause)
C28: optimal | D28: optimal | E28: optimal | F28: optimal | G28: optimal | H28: optimal | I28: optimal | J28: risky | K28: risky | L28: risky | M28: risky | N28: optimal
B29: Debt to Assets Ratio | C29: ='Balance Sheet'!C5/'Balance Sheet'!C36 -> 0.36281476 | D29: ='Balance Sheet'!D5/'Balance Sheet'!D36 -> 0.32886386 | E29: ='Balance Sheet'!E5/'Balance Sheet'!E36 -> 0.32439694 | F29: ='Balance Sheet'!F5/'Balance Sheet'!F36 -> 0.40419279 | G29: ='Balance Sheet'!G5/'Balance Sheet'!G36 -> 0.45397512 | H29: ='Balance Sheet'!H5/'Balance Sheet'!H36 -> 0.45766356 | I29: ='Balance Sheet'!I5/'Balance Sheet'!I36 -> 0.48067312 | J29: ='Balance Sheet'!J5/'Balance Sheet'!J36 -> 0.61206586 | ... N29: ='Balance Sheet'!N5/'Balance Sheet'!N36 -> 0.3811568 | O29: 0.23 | P29: Borrowings/Total Asset | Q29: =AVERAGE(C29:N29) -> 0.44630113 | R29: Firm is consistent with its debt policies and has optimal level of debt. Similar risky trends observed in 2021 and 2022.
C30: optimal | D30: optimal | E30: optimal | F30: optimal | G30: optimal | H30: optimal | I30: optimal | J30: potentially risky | K30: potentially risky | L30: potentially risky | M30: optimal | N30: optimal
B31: Interest Coverage Ratio | C31: ='Profit and Loss Statement'!C9/'Profit and Loss Statement'!C14 -> 2.6394009 | D31: ='Profit and Loss Statement'!D9/'Profit and Loss Statement'!D14 -> 1.6103152 | E31: ='Profit and Loss Statement'!E9/'Profit and Loss Statement'!E14 -> 2.5837696 | F31: ='Profit and Loss Statement'!F9/'Profit and Loss Statement'!F14 -> 1.4988628 | G31: ='Profit and Loss Statement'!G9/'Profit and Loss Statement'!G14 -> 1.5904962 | H31: ='Profit and Loss Statement'!H9/'Profit and Loss Statement'!H14 -> 0.46133333 | I31: ='Profit and Loss Statement'!I9/'Profit and Loss Statement'!I14 -> 1.3960265 | J31: ='Profit and Loss Statement'!J9/'Profit and Loss Statement'!J14 -> 1.1934321 | ... N31: ='Profit and Loss Statement'!N9/'Profit and Loss Statement'!N14 -> 2.100716 | O31: 2.8 | P31: Operating Income/Interest expense | Q31: =AVERAGE(C31:N31) -> 1.5632487 | R31: Highly volatile (less than the industry average since 2019)
C32: Good | D32: Good | E32: Good | F32: Good | G32: Good | H32: Bad | I32: Bad | J32: Bad | K32: Bad | L32: Bad | M32: Bad | N32: Good
B33: Equity to Asset Ratio | C33: ='Balance Sheet'!C3/'Balance Sheet'!C36 -> 0.0077605685 | D33: ='Balance Sheet'!D3/'Balance Sheet'!D36 -> 0.0080450523 | E33: ='Balance Sheet'!E3/'Balance Sheet'!E36 -> 0.0078000867 | F33: ='Balance Sheet'!F3/'Balance Sheet'!F36 -> 0.0066124608 | G33: ='Balance Sheet'!G3/'Balance Sheet'!G36 -> 0.007396855 | H33: ='Balance Sheet'!H3/'Balance Sheet'!H36 -> 0.0070801101 | I33: ='Balance Sheet'!I3/'Balance Sheet'!I36 -> 0.0071777967 | J33: ='Balance Sheet'!J3/'Balance Sheet'!J36 -> 0.0071981285 | ... N33: ='Balance Sheet'!N3/'Balance Sheet'!N36 -> 0.00607845 | O33: 0.0286 | P33: Shareholders Equity/Total Asset | Q33: =AVERAGE(C33:N33) -> 0.0070763889 | R33: Consistency in the result, low Equity/Asset ratio than the industry average.
C34: Bad | D34: Bad | E34: Bad | F34: Bad | G34: Bad | H34: Bad | I34: Bad | J34: Bad | K34: Bad | L34: Bad | M34: Bad | N34: Bad
B36: Turnover Ratios
B37: Inventory Turnover | C37: ='Profit and Loss Statement'!C3/'Balance Sheet'!C38 -> 12.137834 | D37: ='Profit and Loss Statement'!D3/'Balance Sheet'!D38 -> 11.895652 | E37: ='Profit and Loss Statement'!E3/'Balance Sheet'!E38 -> 12.799705 | F37: ='Profit and Loss Statement'!F3/'Balance Sheet'!F38 -> 10.182353 | G37: ='Profit and Loss Statement'!G3/'Balance Sheet'!G38 -> 13.165066 | H37: ='Profit and Loss Statement'!H3/'Balance Sheet'!H38 -> 15.664137 | I37: ='Profit and Loss Statement'!I3/'Balance Sheet'!I38 -> 12.717695 | J37: ='Profit and Loss Statement'!J3/'Balance Sheet'!J38 -> 14.503304 | ... N37: ='Profit and Loss Statement'!N3/'Balance Sheet'!N38 -> 9.8411092 | O37: 2 | Q37: =AVERAGE(C37:N37) -> 11.29551 | R37: Inventory turnover is higher than the industry average ratio(2). Increasing trend observed across the years, suggesting that firm is efficiently utilizing its inventory
C38: Excellent | D38: Excellent | E38: Excellent | F38: Excellent | G38: Excellent | H38: Excellent | I38: Excellent | J38: Excellent | K38: Excellent | L38: Excellent | M38: Excellent | N38: Excellent
B39: Debtors Turnover | C39: ='Profit and Loss Statement'!C3/'Balance Sheet'!C35 -> 6.5378788 | D39: ='Profit and Loss Statement'!D3/'Balance Sheet'!D35 -> 5.6685083 | E39: ='Profit and Loss Statement'!E3/'Balance Sheet'!E35 -> 6.6015951 | F39: ='Profit and Loss Statement'!F3/'Balance Sheet'!F35 -> 6.0418848 | G39: ='Profit and Loss Statement'!G3/'Balance Sheet'!G35 -> 6.8300861 | H39: ='Profit and Loss Statement'!H3/'Balance Sheet'!H35 -> 7.4102334 | I39: ='Profit and Loss Statement'!I3/'Balance Sheet'!I35 -> 6.5336152 | J39: ='Profit and Loss Statement'!J3/'Balance Sheet'!J35 -> 9.7947192 | ... N39: ='Profit and Loss Statement'!N3/'Balance Sheet'!N35 -> 14.443798 | O39: 4.79 | P39: sales/Average Recivable | Q39: =AVERAGE(C39:N39) -> 8.5007261 | R39: Debtor's Turnover ratio is higher than the industry average(4.79) which suggests that firm is able to collect its revenue efficiently
C40: Good | D40: Good | E40: Good | F40: Good | G40: Good | H40: Good | I40: Good | J40: Excellent | K40: Good | L40: Excellent | M40: Excellent | N40: Excellent
B41: Fixed Assets Turnover | C41: ='Profit and Loss Statement'!C3/'Balance Sheet'!C15 -> 1.0036051 | D41: ='Profit and Loss Statement'!D3/'Balance Sheet'!D15 -> 0.85491095 | E41: ='Profit and Loss Statement'!E3/'Balance Sheet'!E15 -> 1.0356292 | F41: ='Profit and Loss Statement'!F3/'Balance Sheet'!F15 -> 0.80991929 | G41: ='Profit and Loss Statement'!G3/'Balance Sheet'!G15 -> 0.94602736 | H41: ='Profit and Loss Statement'!H3/'Balance Sheet'!H15 -> 1.0819135 | I41: ='Profit and Loss Statement'!I3/'Balance Sheet'!I15 -> 0.96142359 | J41: ='Profit and Loss Statement'!J3/'Balance Sheet'!J15 -> 0.53764187 | ... N41: ='Profit and Loss Statement'!N3/'Balance Sheet'!N15 -> 0.95702607 | O41: 0.2461 | P41: Sales/Fixed total asset | Q41: =AVERAGE(C41:N41) -> 0.854725 | R41: Higher than the industry average of 0.2461, reflecting that fixed assets are used efficiently to generate revenue
C42: Excellent | D42: Good | E42: Good | F42: Good | G42: Good | H42: Good | I42: Good | J42: Good | K42: Good | L42: Good | M42: Good | N42: Good
B43: Total Assets Turnover | C43: ='Profit and Loss Statement'!C3/'Balance Sheet'!C37 -> 0.28258948 | D43: ='Profit and Loss Statement'!D3/'Balance Sheet'!D37 -> 0.25609984 | E43: ='Profit and Loss Statement'!E3/'Balance Sheet'!E37 -> 0.25495776 | F43: ='Profit and Loss Statement'!F3/'Balance Sheet'!F37 -> 0.18354607 | G43: ='Profit and Loss Statement'!G3/'Balance Sheet'!G37 -> 0.19492073 | H43: ='Profit and Loss Statement'!H3/'Balance Sheet'!H37 -> 0.22120396 | I43: ='Profit and Loss Statement'!I3/'Balance Sheet'!I37 -> 0.20398411 | J43: ='Profit and Loss Statement'!J3/'Balance Sheet'!J37 -> 0.32091334 | ... N43: ='Profit and Loss Statement'!N3/'Balance Sheet'!N37 -> 0.43359125 | O43: 0.17 | P43: Sales/Average Total Asset | Q43: =AVERAGE(C43:N43) -> 0.28113083 | R43: Higher than the industry average of 0.17, reflecting that assets are used efficiently to generate revenue, consistent with the efficient use of fixed assets
...

Sheet Du Pont Analysis
B1: DU PONT ANALYSIS
B3: ROE - Dupont Equation
C4: 45369 | D4: 45370 | E4: 45371 | F4: 45372 | G4: 45373 | H4: 45374 | I4: 45375 | J4: 45376
B5: Net Profit | C5: ='Profit and Loss Statement'!G18 -> -3151 | D5: ='Profit and Loss Statement'!H18 -> 1769 | E5: ='Profit and Loss Statement'!I18 -> 148 | F5: ='Profit and Loss Statement'!J18 -> 294 | G5: ='Profit and Loss Statement'!K18 -> 2783 | H5: ='Profit and Loss Statement'!L18 -> 3268 | I5: ='Profit and Loss Statement'!M18 -> 2230 | J5: ='Profit and Loss Statement'!N18 -> 3133
B6: Revenue | C6: ='Profit and Loss Statement'!G3 -> 7537 | D6: ='Profit and Loss Statement'!H3 -> 8255 | E6: ='Profit and Loss Statement'!I3 -> 7726 | F6: ='Profit and Loss Statement'!J3 -> 13169 | G6: ='Profit and Loss Statement'!K3 -> 11108 | H6: ='Profit and Loss Statement'!L3 -> 17728 | I6: ='Profit and Loss Statement'!M3 -> 20093 | J6: ='Profit and Loss Statement'!N3 -> 22359
B7: Net Profit Margin (A) | C7: =C5/C6 -> -0.41807085 | D7: =D5/D6 -> 0.21429437 | E7: =E5/E6 -> 0.019156096 | F7: =F5/F6 -> 0.022325158 | G7: =G5/G6 -> 0.25054015 | H7: =H5/H6 -> 0.18434116 | I7: =I5/I6 -> 0.11098392 | J7: =J5/J6 -> 0.14012255
B9: Revenue | C9: =C6 -> 7537 | D9: =D6 -> 8255 | E9: =E6 -> 7726 | F9: =F6 -> 13169 | G9: =G6 -> 11108 | H9: =H6 -> 17728 | I9: =I6 -> 20093 | J9: =J6 -> 22359
B10: Average Total Asset | C10: ='Balance Sheet'!G37 -> 38667 | D10: ='Balance Sheet'!H37 -> 37318.5 | E10: ='Balance Sheet'!I37 -> 37875.5 | F10: ='Balance Sheet'!J37 -> 41036 | G10: ='Balance Sheet'!K37 -> 45804.5 | H10: ='Balance Sheet'!L37 -> 47663 | I10: ='Balance Sheet'!M37 -> 49331 | J10: ='Balance Sheet'!N37 -> 51567
B11: Asset Turnover Ratio (B) | C11: =C9/C10 -> 0.19492073 | D11: =D9/D10 -> 0.22120396 | E11: =E9/E10 -> 0.20398411 | F11: =F9/F10 -> 0.32091334 | G11: =G9/G10 -> 0.24250892 | H11: =H9/H10 -> 0.37194469 | I11: =I9/I10 -> 0.40730981 | J11: =J9/J10 -> 0.43359125
B13: Average Total Asset | C13: =C10 -> 38667 | D13: =D10 -> 37318.5 | E13: =E10 -> 37875.5 | F13: =F10 -> 41036 | G13: =G10 -> 45804.5 | H13: =H10 -> 47663 | I13: =I10 -> 49331 | J13: =J10 -> 51567
B14: Average Shareholder Equity | C14: ='Balance Sheet'!G3+'Balance Sheet'!G4 -> 12988 | D14: ='Balance Sheet'!H3+'Balance Sheet'!H4 -> 15689 | E14: ='Balance Sheet'!I3+'Balance Sheet'!I4 -> 15261 | F14: ='Balance Sheet'!J3+'Balance Sheet'!J4 -> 9879 | G14: ='Balance Sheet'!K3+'Balance Sheet'!K4 -> 10880 | H14: ='Balance Sheet'!L3+'Balance Sheet'!L4 -> 13700 | I14: ='Balance Sheet'!M3+'Balance Sheet'!M4 -> 15788 | J14: ='Balance Sheet'!N3+'Balance Sheet'!N4 -> 18366
B15: Equity Multiplier (C) | C15: =C13/C14 -> 2.9771327 | D15: =D13/D14 -> 2.3786411 | E15: =E13/E14 -> 2.4818492 | F15: =F13/F14 -> 4.1538617 | G15: =G13/G14 -> 4.2099724 | H15: =H13/H14 -> 3.4790511 | I15: =I13/I14 -> 3.1245883 | J15: =J13/J14 -> 2.8077426
B17: Return on Equity (A*B*C) | C17: =C7*C11*C15 -> -0.24260856 | D17: =D7*D11*D15 -> 0.11275416 | E17: =E7*E11*E15 -> 0.0096979228 | F17: =F7*F11*F15 -> 0.029760097 | G17: =G7*G11*G15 -> 0.25579044 | H17: =H7*H11*H15 -> 0.23854015 | I17: =I7*I11*I15 -> 0.14124652 | J17: =J7*J11*J15 -> 0.17058695 | K17: This shows that the calculated Du Pont values are close to actual industry values
C18: -0.2425 | D18: 0.1246 | E18: 0.0107 | F18: 0.0545 | G18: 0.2557 | H18: 0.2385 | I18: 0.1412 | J18: 0.1705
B19: ROA - Dupont Equation
C20: 45369 | D20: 45370 | E20: 45371 | F20: 45372 | G20: 45373 | H20: 45374 | I20: 45375 | J20: 45376
B21: Net Profit | C21: =C5 -> -3151 | D21: =D5 -> 1769 | E21: =E5 -> 148 | F21: =F5 -> 294 | G21: =G5 -> 2783 | H21: =H5 -> 3268 | I21: =I5 -> 2230 | J21: =J5 -> 3133
B22: Revenue | C22: =C6 -> 7537 | D22: =D6 -> 8255 | E22: =E6 -> 7726 | F22: =F6 -> 13169 | G22: =G6 -> 11108 | H22: =H6 -> 17728 | I22: =I6 -> 20093 | J22: =J6 -> 22359
B23: Net Profit Margin (A) | C23: =C7 -> -0.41807085 | D23: =D7 -> 0.21429437 | E23: =E7 -> 0.019156096 | F23: =F7 -> 0.022325158 | G23: =G7 -> 0.25054015 | H23: =H7 -> 0.18434116 | I23: =I7 -> 0.11098392 | J23: =J7 -> 0.14012255
B25: Revenue | C25: =C9 -> 7537 | D25: =D9 -> 8255 | E25: =E9 -> 7726 | F25: =F9 -> 13169 | G25: =G9 -> 11108 | H25: =H9 -> 17728 | I25: =I9 -> 20093 | J25: =J9 -> 22359
B26: Average Total Asset | C26: =C10 -> 38667 | D26: =D10 -> 37318.5 | E26: =E10 -> 37875.5 | F26: =F10 -> 41036 | G26: =G10 -> 45804.5 | H26: =H10 -> 47663 | I26: =I10 -> 49331 | J26: =J10 -> 51567
B27: Asset Turnover Ratio (B) | C27: =C11 -> 0.19492073 | D27: =D11 -> 0.22120396 | E27: =E11 -> 0.20398411 | F27: =F11 -> 0.32091334 | G27: =G11 -> 0.24250892 | H27: =H11 -> 0.37194469 | I27: =I11 -> 0.40730981 | J27: =J11 -> 0.43359125
B29: Return on Asset (A*B) | C29: =C23*C27 -> -0.081490677 | D29: =D23*D27 -> 0.047402763 | E29: =E23*E27 -> 0.0039075392 | F29: =F23*F27 -> 0.007164441 | G29: =G23*G27 -> 0.060758222 | H29: =H23*H27 -> 0.068564715 | I29: =I23*I27 -> 0.045204841 | J29: =J23*J27 -> 0.06075591 | K29: This shows that the calculated Du Pont values are close to actual industry values
C30: -0.0863 | D30: 0.0463 | E30: 0.0039 | F30: 0.0214 | G30: 0.059 | H30: 0.0678 | I30: 0.0441 | J30: 0.0595

Sheet Market Return
B1: Returns on Market (To calculate Rm) | E1: Nifty 50 -25 Years Market Return
B2: Year | C2: Annual
B3: 2000 | C3: -0.1465
B4: 2001 | C4: -0.1618
B5: 2002 | C5: 0.0325 | E5: Average Return | G5: =AVERAGE(C3:C27) -> 0.153348
B6: 2003 | C6: 0.719 | E6: Dividend Yield | G6: 0.0129
B7: 2004 | C7: 0.1068 | E7: Total Market return | G7: =SUM(G5:G6) -> 0.166248
B8: 2005 | C8: 0.3634
B9: 2006 | C9: 0.3983
B10: 2007 | C10: 0.5477
B11: 2008 | C11: -0.5179
B12: 2009 | C12: 0.7576
B13: 2010 | C13: 0.1795
B14: 2011 | C14: -0.2462
B15: 2012 | C15: 0.277
B16: 2013 | C16: 0.0676
B17: 2014 | C17: 0.3139
B18: 2015 | C18: -0.0406
B19: 2016 | C19: 0.0301
... B27: 2024 | C27: 0.0875

Sheet Beta Calculation
AC1: Peers to Our companies
C3: NIFTY RETURNS | F3: TATA POWER | J3: Beta Drifting
B4: Date | C4: Price | D4: Change % | F4: Price | G4: Change % | Z4: NTPC | AC4: Power Grid Corporation of India | AF4: NHPC | AI4: Adani Green
B5: 01/26/2025 | C5: 23508.4 | D5: 0.018 | F5: 364.5 | G5: 0.003 | J5: Levered Raw beta | K5: =K19 -> 1.4005939 | Z5: Price | AA5: Change % | AC5: Price | AD5: Change % | AF5: Price | AG5: Change % | AI5: Price | AJ5: Change %
B6: 01/19/2025 | C6: 23092.2 | D6: -0.0048 | F6: 363.4 | G6: -0.0273 | J6: Raw Beta weight | K6: 0.75 | T6: HERE TAKE NOTE ALL THE DATA HAS BEEN CHANGED TO 5 YEAR | Z6: 324 | AA6: 0.0011 | AC6: 301.65 | AD6: 0.0196 | AF6: 80.55 | AG6: 0.0477 | AI6: 997.55 | AJ6: -0.0144
B7: 45992 | C7: 23203.2 | D7: -0.0097 | F7: 373.6 | G7: 0.0484 | Z7: 323.65 | AA7: -0.0077 | AC7: 295.85 | AD7: -0.0223 | AF7: 76.88 | AG7: -0.0438 | AI7: 1012.1 | AJ7: -0.0613
B8: 45778 | C8: 23431.5 | D8: -0.0239 | F8: 356.35 | G8: -0.1016 | J8: Market Beta | K8: 1 | Z8: 326.15 | AA8: 0.0581 | AC8: 302.6 | AD8: 0.0097 | AF8: 80.4 | AG8: 0.0496 | AI8: 1078.2 | AJ8: 0.1433
B9: 12/29/2024 | C9: 24004.75 | D9: 0.008 | F9: 396.65 | G9: -0.0059 | J9: Market Beta weight | K9: =1-K6 -> 0.25 | Z9: 308.25 | AA9: -0.093 | AC9: 299.7 | AD9: -0.0517 | AF9: 76.6 | AG9: -0.0781 | AI9: 943.05 | AJ9: -0.0917
B10: 12/22/2024 | C10: 23813.4 | D10: 0.0096 | F10: 399 | G10: -0.0052 | Z10: 339.85 | AA10: 0.0145 | AC10: 316.05 | AD10: 0.0215 | AF10: 83.09 | AG10: 0.0344 | AI10: 1038.25 | AJ10: -0.0149
B11: 12/15/2024 | C11: 23587.5 | D11: -0.0477 | F11: 401.1 | G11: -0.0638 | J11: Adj Beta for TATA POWER | K11: =K5*K6+K8*K9 -> 1.3004454 | L11: mean reversion tendencies toward 1, using 75% weight to the levered beta and 25% weight to the market Beta thus to come towards mean it will get adjusted to 1.52 from 1.69 | Z11: 335 | AA11: 0.0053 | AC11: 309.4 | AD11: -0.0203 | AF11: 80.33 | AG11: -0.014 | AI11: 1054 | AJ11: 0.019
B12: 45516 | C12: 24768.3 | D12: 0.0037 | F12: 428.45 | G12: -0.0256 | Z12: 333.25 | AA12: -0.0669 | AC12: 315.8 | AD12: -0.0541 | AF12: 81.47 | AG12: -0.0465 | AI12: 1034.35 | AJ12: -0.1369
B13: 45303 | C13: 24677.8 | D13: 0.0227 | F13: 439.7 | G13: 0.0617 | Z13: 357.15 | AA13: -0.0334 | AC13: 333.85 | AD13: 0.0151 | AF13: 85.44 | AG13: 0.0067 | AI13: 1198.4 | AJ13: -0.0101
B14: 11/24/2024 | C14: 24131.1 | D14: 0.0094 | F14: 414.15 | G14: 0.001 | Z14: 369.5 | AA14: 0.0161 | AC14: 328.9 | AD14: -0.0015 | AF14: 84.87 | AG14: 0.0421 | AI14: 1210.65 | AJ14: -0.0855
B15: 11/17/2024 | C15: 23907.25 | D15: 0.0159 | F15: 413.75 | G15: 0.0225 | T15: Peers Beta using Historical data | Z15: 363.65 | AA15: -0.0049 | AC15: 329.4 | AD15: -0.0224 | AF15: 81.44 | AG15: 0.0288 | AI15: 1323.9 | AJ15: 0.2587
B16: 45576 | C16: 23532.7 | D16: -0.0255 | F16: 404.65 | G16: -0.0649 | T16: Beta NTPC | U16: =SLOPE(AA6:AA213,D5:D212) -> 0.77953163 | Z16: 365.45 | AA16: -0.0189 | AC16: 336.95 | AD16: 0.0796 | AF16: 79.16 | AG16: 0.01 | AI16: 1051.8 | AJ16: -0.2942
B17: 45362 | C17: 24148.2 | D17: -0.0064 | F17: 432.75 | G17: -0.0285 | I17: Slope Method | J17: Beta 1 TATA POWER | K17: =SLOPE(G5:G212,D5:D212) -> 1.4005939 | T17: Beta Power Grid | U17: =SLOPE(AD6:AD213,D5:D212) -> 0.4919556 | Z17: 372.5 | AA17: -0.0632 | AC17: 312.1 | AD17: -0.0131 | AF17: 78.38 | AG17: -0.0482 | AI17: 1490.3 | AJ17: -0.0677
B18: 10/27/2024 | C18: 24304.35 | D18: 0.0051 | F18: 445.45 | G18: 0.0553 | I18: Covariance Method | J18: Beta 2 TATA POWER | K18: {=_xlfn.COVARIANCE.S(D5:D212,G5:G212/_xlfn.VAR.S(D5:D212))} -> 1.4005939 | T18: Beta NHPC Energy | U18: =SLOPE(AG6:AG213,D5:D212) -> 0.82920816 | Z18: 397.65 | AA18: -0.0333 | AC18: 316.25 | AD18: -0.018 | AF18: 82.35 | AG18: -0.0212 | AI18: 1598.55 | AJ18: -0.0209
B19: 10/20/2024 | C19: 24180.8 | D19: -0.0271 | F19: 422.1 | G19: -0.0693 | I19: Statistical Regression | J19: Beta 3 TATA POWER | K19: =K41 -> 1.4005939 | T19: Beta Adani green | U19: =SLOPE(AJ6:AJ213,D5:D212) -> 1.0651349 | Z19: 411.35 | AA19: 0.0312 | AC19: 322.05 | AD19: 0.0198 | AF19: 84.13 | AG19: 0.0717 | AI19: 1632.65 | AJ19: -0.0069
B20: 10/13/2024 | C20: 24854.05 | D20: -0.0044 | F20: 453.55 | G20: -0.0165 | Z20: 398.9 | AA20: -0.0613 | AC20: 315.8 | AD20: -0.0489 | AF20: 78.5 | AG20: -0.0669 | AI20: 1644 | AJ20: -0.053
B21: 45453 | C21: 24964.25 | D21: -0.002 | F21: 461.15 | G21: -0.0118 | Z21: 424.95 | AA21: 0.0058 | AC21: 332.05 | AD21: 0.0061 | AF21: 84.13 | AG21: -0.0747 | AI21: 1736.05 | AJ21: -0.0313
B22: 09/29/2024 | C22: 25014.6 | D22: -0.0445 | F22: 466.65 | G22: -0.0388 | Z22: 422.5 | AA22: -0.0185 | AC22: 330.05 | AD22: -0.026 | AF22: 90.92 | AG22: -0.0241 | AI22: 1792.2 | AJ22: -0.005
B23: 09/22/2024 | C23: 26178.95 | D23: 0.015 | F23: 485.5 | G23: 0.0931 | Z23: 430.45 | AA23: -0.0148 | AC23: 338.85 | AD23: -0.0435 | AF23: 93.17 | AG23: -0.0228 | AI23: 1801.2 | AJ23: -0.0912
B24: 09/15/2024 | C24: 25790.95 | D24: 0.0171 | F24: 444.15 | G24: 0.0053 | J24: SUMMARY OUTPUT | Z24: 436.9 | AA24: 0.0305 | AC24: 354.25 | AD24: 0.0393 | AF24: 95.34 | AG24: 0.0073 | AI24: 1981.85 | AJ24: -0.011
B25: 45513 | C25: 25356.5 | D25: 0.0203 | F25: 441.8 | G25: 0.0595 | Z25: 423.95 | AA25: 0.0562 | AC25: 340.85 | AD25: 0.0107 | AF25: 94.65 | AG25: 0.0039 | AI25: 2003.95 | AJ25: 0.1207
B26: 45300 | C26: 24852.15 | D26: -0.0152 | F26: 417 | G26: -0.0406 | J26: Regression Statistics | Z26: 401.4 | AA26: 0.0167 | AC26: 337.25 | AD26: 0.0226 | AF26: 94.28 | AG26: -0.0188 | AI26: 1788.2 | AJ26: -0.0403
B27: 08/25/2024 | C27: 25235.9 | D27: 0.0166 | F27: 434.65 | G27: 0.04 | J27: Multiple R | K27: 0.52250879 | Z27: 394.8 | AA27: -0.0514 | AC27: 329.8 | AD27: -0.0225 | AF27: 96.09 | AG27: -0.0003 | AI27: 1863.3 | AJ27: 0.0137
B28: 08/18/2024 | C28: 24823.15 | D28: 0.0115 | F28: 417.95 | G28: 0.0104 | J28: R Square | K28: 0.27301544 | L28: EXPLAING THE SIGNIFICANCE OF R2 | Z28: 416.2 | AA28: 0.0355 | AC28: 337.4 | AD28: 0.0034 | AF28: 96.12 | AG28: -0.01 | AI28: 1838.15 | AJ28: -0.033
B29: 45604 | C29: 24541.15 | D29: 0.0071 | F29: 413.65 | G29: -0.0098 | J29: Adjusted R Square | K29: 0.26948638 | Z29: 401.95 | AA29: 0.0098 | AC29: 336.25 | AD29: -0.0069 | AF29: 97.09 | AG29: 0.0314 | AI29: 1900.9 | AJ29: 0.0382
B30: 45390 | C30: 24367.5 | D30: -0.0142 | F30: 417.75 | G30: -0.0925 | J30: Standard Error | K30: 0.041590954 | Z30: 398.05 | AA30: -0.0307 | AC30: 338.6 | AD30: -0.0214 | AF30: 94.13 | AG30: -0.0372 | AI30: 1831 | AJ30: 0.0282
B31: 07/28/2024 | C31: 24717.7 | D31: -0.0047 | F31: 460.35 | G31: 0.0352 | J31: Observations | K31: 208 | Z31: 410.65 | AA31: -0.0216 | AC31: 346 | AD31: -0.0342 | AF31: 97.77 | AG31: -0.0536 | AI31: 1780.85 | AJ31: -0.0534
B32: 07/21/2024 | C32: 24834.85 | D32: 0.0124 | F32: 444.7 | G32: 0.0738 | Z32: 419.7 | AA32: 0.059 | AC32: 358.25 | AD32: 0.0408 | AF32: 103.31 | AG32: -0.0125 | AI32: 1881.4 | AJ32: 0.0431
B33: 07/14/2024 | C33: 24530.9 | D33: 0.0012 | F33: 414.15 | G33: -0.0458 | J33: ANOVA | Z33: 396.3 | AA33: 0.0868 | AC33: 344.2 | AD33: 0.0361 | AF33: 104.62 | AG33: -0.0155 | AI33: 1803.7 | AJ33: 0.0467
B34: 45480 | C34: 24502.15 | D34: 0.0073 | F34: 434.05 | G34: -0.0134 | K34: df | L34: SS | M34: MS | N34: F | O34: Significance F | Z34: 364.65 | AA34: -0.0331 | AC34: 332.2 | AD34: -0.0318 | AF34: 106.27 | AG34: -0.0597 | AI34: 1723.3 | AJ34: -0.0069
B35: 06/30/2024 | C35: 24323.85 | D35: 0.013 | F35: 439.95 | G35: -0.0015 | J35: Regression | K35: 1 | L35: 0.13382184 | M35: 0.13382184 | N35: 77.362275 | O35: 5.7291005e-16 | Z35: 377.15 | AA35: -0.007 | AC35: 343.1 | AD35: 0.0109 | AF35: 113.02 | AG35: 0.0886 | AI35: 1735.25 | AJ35: -0.0109
B36: 06/23/2024 | C36: 24010.6 | D36: 0.0217 | F36: 440.6 | G36: 0.0043 | J36: Residual | K36: 206 | L36: 0.35634034 | M36: 0.0017298075 | Z36: 379.8 | AA36: 0.0038 | AC36: 339.4 | AD36: 0.0255 | AF36: 103.82 | AG36: 0.031 | AI36: 1754.3 | AJ36: -0.0193
B37: 06/16/2024 | C37: 23501.1 | D37: 0.0015 | F37: 438.7 | G37: -0.0222 | J37: Total | K37: 207 | L37: 0.49016218 | Z37: 378.35 | AA37: 0.0516 | AC37: 330.95 | AD37: 0.0153 | AF37: 100.7 | AG37: -0.0006 | AI37: 1788.8 | AJ37: 0.0047
B38: 45541 | C38: 23465.6 | D38: 0.0075 | F38: 448.65 | G38: 0.0115 | Z38: 359.8 | AA38: -0.0235 | AC38: 325.95 | AD38: 0.0138 | AF38: 100.76 | AG38: -0.0178 | AI38: 1780.45 | AJ38: -0.0143
B39: 45328 | C39: 23290.15 | D39: 0.0337 | F39: 443.55 | G39: 0.0156 | K39: Coefficients | L39: Standard Error | M39: t Stat | N39: P-value | O39: Lower 95% | P39: Upper 95% | Q39: Lower 95.0% | R39: Upper 95.0% | Z39: 368.45 | AA39: 0.0218 | AC39: 321.5 | AD39: 0.0393 | AF39: 102.59 | AG39: -0.0059 | AI39: 1806.3 | AJ39: -0.0311
B40: 05/26/2024 | C40: 22530.7 | D40: -0.0186 | F40: 436.75 | G40: -0.0234 | J40: Intercept | K40: 0.004736586 | L40: 0.0029079621 | M40: 1.6288335 | N40: 0.10487656 | O40: -0.00099659695 | P40: 0.010469769 | Q40: -0.00099659695 | R40: 0.010469769 | Z40: 360.6 | AA40: 0.0045 | AC40: 309.35 | AD40: -0.0021 | AF40: 103.2 | AG40: -0.0378 | AI40: 1864.25 | AJ40: -0.0231
B41: 05/19/2024 | C41: 22957.1 | D41: 0.0219 | F41: 447.2 | G41: 0.025 | J41: Change % | K41: 1.4005939 | L41: 0.15923833 | M41: 8.7955827 | N41: 5.7291005e-16 | O41: 1.0866481 | P41: 1.7145397 | Q41: 1.0866481 | R41: 1.7145397 | Z41: 359 | AA41: -0.0425 | AC41: 310 | AD41: -0.0276 | AF41: 107.25 | AG41: 0.0469 | AI41: 1908.35 | AJ41: -0.0095
...

Sheet Bottom_Up(Beta) & Ke
A1: This sheets does a peer comparison of Tata Power and power sector firms on basis of their (Debt to equity ratio) , and later using that and levered and unlevered beta by bottom Up approach, we have calculated the Required Returns or Cost of equity (Ke by CAPM model)
B5: Peer Comparison
B7: Name | C7: Total debt | D7: Total Equity | E7: Tax Rate | F7: Debt/. Equity | G7: Debt/. Capital | H7: Levered Beta | I7: Unlevered Beta
B9: Tata Power Co. | C9: 62865.8 | D9: 130641.46 | E9: 0.3 | F9: =C9/D9 -> 0.48120865 | G9: =C9/(C9+D9) -> 0.32487567 | H9: ='Beta Calculation'!K5 -> 1.4005939 | I9: =H9/(1+(1-E9)*F9) -> 1.0476853
B10: NTPC | C10: 250096.15 | D10: 328038.22 | E10: 0.3 | F10: =C10/D10 -> 0.76239942 | G10: =C10/(C10+D10) -> 0.43259173 | H10: ='Beta Calculation'!U16 -> 0.77953163 | I10: =H10/(1+(1-E10)*F10) -> 0.50827541
B11: Power Grid corp | C11: 131030.21 | D11: 278320.57 | E11: 0.3 | F11: =C11/D11 -> 0.47078881 | G11: =C11/(C11+D11) -> 0.32009273 | H11: ='Beta Calculation'!U17 -> 0.4919556 | I11: =H11/(1+(1-E11)*F11) -> 0.37001602
B12: Adani Green | C12: 80040 | D12: 164790.87 | E12: 0.3 | F12: =C12/D12 -> 0.48570652 | G12: =C12/(C12+D12) -> 0.32691956 | H12: ='Beta Calculation'!U19 -> 1.0651349 | I12: =H12/(1+(1-E12)*F12) -> 0.79488003
B13: NHPC Ltd | C13: 39556.78 | D13: 85935.27 | E13: 0.3 | F13: =C13/D13 -> 0.46030902 | G13: =C13/(C13+D13) -> 0.31521343 | H13: ='Beta Calculation'!U18 -> 0.82920816 | I13: =H13/(1+(1-E13)*F13) -> 0.62713503
D15: Average | E15: =AVERAGE(E9:E13) -> 0.3 | F15: =AVERAGE(F9:F13) -> 0.53208248 | G15: =AVERAGE(G9:G13) -> 0.34393863 | H15: =AVERAGE(H9:H13) -> 0.91328484 | I15: =AVERAGE(I9:I13) -> 0.66959835
D16: Median | E16: =MEDIAN(E9:E13) -> 0.3 | F16: =MEDIAN(F9:F13) -> 0.48120865 | G16: =MEDIAN(G9:G13) -> 0.32487567 | H16: =MEDIAN(H9:H13) -> 0.82920816 | I16: =MEDIAN(I9:I13) -> 0.62713503
D17: *Tax rate is take as 30% which is market standard
B20: Current | H20: Companies average beta (unlevered) | J20: =I15 -> 0.66959835
B21: Total Debt | D21: =C9 -> 62865.8 | E21: =D21/D23 -> 0.32487567 | H21: Current debt/equity | J21: =E25 -> 0.48120865
B22: Market Capitalization | D22: =D9 -> 130641.46 | E22: =D22/D23 -> 0.67512433 | H22: Tax rate | J22: =E15 -> 0.3
B23: Total Capitalization | D23: =D21+D22 -> 193507.26 | E23: =E21+E22 -> 1 | H23: Levered Beta | J23: =J20*(1+(1-E15)*J21) -> 0.89514991
B25: Debt/Equity | E25: =E21/E22 -> 0.48120865 | H25: Risk free rate (India) | J25: 0.06316
H26: Market return (NIFTY 50 : 25 years) | J26: 0.166248
H27: Equity Risk premium | J27: =J26-J25 -> 0.103088
H28: Ke | J28: =J25+J27*J23 -> 0.15543921
H29: Formula used for calculation (CAPM model) -> Ke = [rf+ (rm-rf)*beta]

Sheet Kd
B1: This is a table that relates the interest coverage ratio of a firm to a "synthetic" rating and a default spread that goes with that rating. The link between interest coverage ratios and ratings was developed by looking at all rated companies in the United States. The default spreads are obtained from traded bonds. Adding that number to a riskfree rate should yield the pre-tax cost of borrowing for a firm.
B5: Date of Analysis: Data used is as of January 2025 | L5: *Since this synthetic ratings are US based we are adjusting the default spread for India
L6: USA | M6: 0 | N6: 0.0433 | O6: 0 | P6: 0.25
L7: India | M7: 0.0218 | N7: 0.0726 | O7: 0.0293 | P7: 0.3
B8: For large non-financial service firms | G8: For financial service firms (default spreads are slighty different) | M8: Adj. Default Spread | N8: Equity Risk Premium | O8: Country Risk Premium | P8: Corporate Tax Rate
B9: If interest coverage ratio is | G9: If long term interest coverage ratio is
B10: > | C10: ≤ to | D10: Rating is | E10: Spread is | G10: greater than | H10: ≤ to | I10: Rating is | J10: Spread is | L10: 1) | M10: Tata Power rating | N10: Ba1 | O10: ='Bottom_Up(Beta) & Ke'!J25+Kd!E19+Kd!M7 -> 0.10046 | P10: kd = RFR (India) + Default spread of the BA rated bond (India) (adjusted) (by US based spread + adjusted default spread of India relative to US)
B11: -100000 | C11: 0.199999 | D11: D2/D | E11: 0.19 | G11: -100000 | H11: 0.049999 | I11: D2/D | J11: 0.19 | M11: (Moody)
B12: 0.2 | C12: 0.649999 | D12: C2/C | E12: 0.155 | G12: 0.05 | H12: 0.099999 | I12: C2/C | J12: 0.155 | L12: 2) | M12: Formula Used | N12: - | O12: =('Profit and Loss Statement'!N14/'Balance Sheet'!N5)*100 -> 10.440546 | P12: Kd = interest expenses/ (interest bearing debt)
B13: 0.65 | C13: 0.799999 | D13: Ca2/CC | E13: 0.101 | G13: 0.1 | H13: 0.199999 | I13: Ca2/CC | J13: 0.101
B14: 0.8 | C14: 1.249999 | D14: Caa/CCC | E14: 0.0728 | G14: 0.2 | H14: 0.299999 | I14: Caa/CCC | J14: 0.0728 | L14: Cost of debt after tax | O14: =O10*(1-0.3) -> 0.070322
B15: 1.25 | C15: 1.499999 | D15: B3/B- | E15: 0.0442 | G15: 0.3 | H15: 0.399999 | I15: B3/B- | J15: 0.0442
B16: 1.5 | C16: 1.749999 | D16: B2/B | E16: 0.03 | G16: 0.4 | H16: 0.499999 | I16: B2/B | J16: 0.03
B17: 1.75 | C17: 1.999999 | D17: B1/B+ | E17: 0.0261 | G17: 0.5 | H17: 0.599999 | I17: B1/B+ | J17: 0.0261
B18: 2 | C18: 2.2499999 | D18: Ba2/BB | E18: 0.0183 | G18: 0.6 | H18: 0.749999 | I18: Ba2/BB | J18: 0.0183
B19: 2.25 | C19: 2.49999 | D19: Ba1/BB+ | E19: 0.0155 | G19: 0.75 | H19: 0.899999 | I19: Ba1/BB+ | J19: 0.0155
B20: 2.5 | C20: 2.999999 | D20: Baa2/BBB | E20: 0.012 | G20: 0.9 | H20: 1.199999 | I20: Baa2/BBB | J20: 0.012
B21: 3 | C21: 4.249999 | D21: A3/A- | E21: 0.0095 | G21: 1.2 | H21: 1.49999 | I21: A3/A- | J21: 0.0095
B22: 4.25 | C22: 5.499999 | D22: A2/A | E22: 0.0085 | G22: 1.5 | H22: 1.99999 | I22: A2/A | J22: 0.0085
B23: 5.5 | C23: 6.499999 | D23: A1/A+ | E23: 0.0077 | G23: 2 | H23: 2.49999 | I23: A1/A+ | J23: 0.0077
B24: 6.5 | C24: 8.499999 | D24: Aa2/AA | E24: 0.006 | G24: 2.5 | H24: 2.99999 | I24: Aa2/AA | J24: 0.006
B25: 8.5 | C25: 100000 | D25: Aaa/AAA | E25: 0.0045 | G25: 3 | H25: 100000 | I25: Aaa/AAA | J25: 0.0045
B27: For smaller and riskier non-financial service firms
B28: If interest coverage ratio is
B29: greater than | C29: ≤ to | D29: Rating is | E29: Spread is
B30: -100000 | C30: 0.499999 | D30: D2/D | E30: 0.19
B31: 0.5 | C31: 0.799999 | D31: C2/C | E31: 0.155
B32: 0.8 | C32: 1.249999 | D32: Ca2/CC | E32: 0.101
B33: 1.25 | C33: 1.499999 | D33: Caa/CCC | E33: 0.0728
B34: 1.5 | C34: 1.999999 | D34: B3/B- | E34: 0.0442
B35: 2 | C35: 2.499999 | D35: B2/B | E35: 0.03
B36: 2.5 | C36: 2.999999 | D36: B1/B+ | E36: 0.0261
B37: 3 | C37: 3.499999 | D37: Ba2/BB | E37: 0.0183
B38: 3.5 | C38: 3.9999999 | D38: Ba1/BB+ | E38: 0.0155
B39: 4 | C39: 4.499999 | D39: Baa2/BBB | E39: 0.012
B40: 4.5 | C40: 5.999999 | D40: A3/A- | E40: 0.0095
B41: 6 | C41: 7.499999 | D41: A2/A | E41: 0.0085
... B44: 12.5 | C44: 100000 | D44: Aaa/AAA | E44: 0.0045

Sheet WACC
A1: WACC
A3: Wt. of debt | B3: ='Bottom_Up(Beta) & Ke'!E21 -> 0.32487567
A4: Cost of debt(pre-tax) | B4: =Kd!O10 -> 0.10046
A5: Cost of debt @30 TAX | B5: =Kd!O14 -> 0.070322
A6: Calculating using synthetic rating adjusted to indian economy
A8: Wt of Equity | B8: ='Bottom_Up(Beta) & Ke'!E22 -> 0.67512433
A9: Cost of Equity | B9: ='Bottom_Up(Beta) & Ke'!J28 -> 0.15543921
A10: Calculated using CAPM model
A12: WACC | B12: =B9*B8+B5*B3 -> 0.1277867

Sheet Data_sheet for growth
B1: HERE WE WILL TAKE CONSOLIDATES/STANDALONE BASED ON THE COMPANY
C2: 41699 | D2: 42064 | E2: 42430 | F2: 42795 | G2: 43160 | H2: 43525 | I2: 43891 | J2: 44256 | K2: 44621 | L2: 44986 | M2: 45352 | N2: 45717
B3: Equity Capital | C3: 237 | D3: 270 | E3: 270 | F3: 270 | G3: 270 | H3: 270 | I3: 270 | J3: 320 | K3: 320 | L3: 320 | M3: 320 | N3: 320
B4: Reserves | C4: 12164 | D4: 14048 | E4: 11363 | F4: 12944 | G4: 16129 | H4: 18035 | I4: 19296 | J4: 22003 | K4: 22122 | L4: 28468 | M4: 32036 | N4: 35521
B5: Borrowings -
B6: Long term Borrowings | C6: 30470 | D6: 32393 | E6: 22414 | F6: 25143 | G6: 22356 | H6: 31139 | I6: 32695 | J6: 30045 | K6: 32730 | L6: 30708 | M6: 37392 | N6: 44130
B7: Short term Borrowings | C7: 4707 | D7: 4587 | E7: 14589 | F7: 16280 | G7: 18827 | H7: 13875 | I7: 11844 | J7: 13126 | K7: 14860 | L7: 18266 | M7: 12088 | N7: 14016
B8: Lease Liabilities | C8: 0 | D8: 0 | E8: 0 | F8: 0 | G8: 0 | H8: 0 | I8: 279 | J8: 2749 | K8: 2859 | L8: 3054 | M8: 3086 | N8: 3094
B9: Other Borrowings | C9: 4996 | D9: 3627 | E9: 1846 | F9: 7393 | G9: 7406 | H9: 3491 | I9: 3836 | J9: 0 | K9: 0 | L9: 0 | M9: 0 | N9: 0
B10: Other Liabilities -
B11: Trade Payables | C11: 4574 | D11: 5235 | E11: 4401 | F11: 5529 | G11: 5610 | H11: 5481 | I11: 5095 | J11: 7146 | K11: 10460 | L11: 7407 | M11: 14093 | N11: 13984
B12: Advance from Customers | C12: 560 | D12: 377 | E12: 220 | F12: 413 | G12: 559 | H12: 485 | I12: 782 | J12: 1209 | K12: 1180 | L12: 2458 | M12: 2197 | N12: 1579
B13: Other liability items | C13: 11402 | D13: 12154 | E13: 13204 | F13: 12989 | G13: 8718 | H13: 9129 | I13: 9962 | J13: 18342 | K13: 23687 | L13: 31104 | M13: 30742 | N13: 35158
B14: Total Liabilities | C14: 71383 | D14: 75185 | E14: 70057 | F14: 82829 | G14: 81892 | H14: 84073 | I14: 89674 | J14: 98655 | K14: 112550 | L14: 128096 | M14: 139054 | N14: 156193
B16: Fixed Assets -
B17: Land | C17: 939 | D17: 1431 | E17: 919 | F17: 1079 | G17: 974 | H17: 1032 | I17: 2071 | J17: 2186 | K17: 2284 | L17: 2672 | M17: 3352 | N17: 4087
B18: Building | C18: 2687 | D18: 2927 | E18: 2696 | F18: 2792 | G18: 2906 | H18: 2938 | I18: 3058 | J18: 3826 | K18: 4043 | L18: 4432 | M18: 4503 | N18: 5615
B19: Plant Machinery | C19: 40297 | D19: 41848 | E19: 36484 | F19: 44014 | G19: 43914 | H19: 44924 | I19: 47425 | J19: 48607 | K19: 52664 | L19: 55799 | M19: 59919 | N19: 68397
B20: Equipments | C20: 5561 | D20: 6129 | E20: 4941 | F20: 5317 | G20: 5812 | H20: 6364 | I20: 6967 | J20: 11790 | K20: 15200 | L20: 18485 | M20: 22097 | N20: 26523
B21: Furniture n fittings | C21: 114 | D21: 127 | E21: 133 | F21: 137 | G21: 122 | H21: 120 | I21: 118 | J21: 134 | K21: 144 | L21: 167 | M21: 187 | N21: 207
B22: Railway sidings | C22: 104 | D22: 100 | E22: 94 | F22: 96 | G22: 99 | H22: 103 | I22: 104 | J22: 0 | K22: 0 | L22: 0 | M22: 0 | N22: 0
B23: Vehicles | C23: 259 | D23: 250 | E23: 110 | F23: 220 | G23: 250 | H23: 245 | I23: 235 | J23: 228 | K23: 225 | L23: 247 | M23: 300 | N23: 327
B24: Intangible Assets | C24: 6395 | D24: 6706 | E24: 99 | F24: 1768 | G24: 1666 | H24: 1654 | I24: 1646 | J24: 1800 | K24: 1864 | L24: 1865 | M24: 1903 | N24: 1807
B25: Other fixed assets | C25: 5011 | D25: 5404 | E25: 2192 | F25: 4211 | G25: 4265 | H25: 4233 | I25: 5441 | J25: 5584 | K25: 5876 | L25: 6229 | M25: 6519 | N25: 6722
B26: Gross Block | C26: 61367 | D26: 64925 | E26: 47667 | F26: 59634 | G26: 60008 | H26: 61613 | I26: 67064 | J26: 74156 | K26: 82301 | L26: 89897 | M26: 98781 | N26: 113686
B27: Accumulated Depreciation | C27: 17973 | D27: 20199 | E27: 11254 | F27: 13040 | G27: 15352 | H27: 17308 | I27: 19398 | J27: 21976 | K27: 24911 | L27: 28150 | M27: 31470 | N27: 35205
B28: NET BLOCK | C28: =C26-C27 -> 43394 | D28: =D26-D27 -> 44726 | E28: =E26-E27 -> 36413 | F28: =F26-F27 -> 46594 | G28: =G26-G27 -> 44656 | H28: =H26-H27 -> 44305 | I28: =I26-I27 -> 47666 | J28: =J26-J27 -> 52180 | ... N28: =N26-N27 -> 78481
B30: CWIP | C30: 3389 | D30: 3323 | E30: 1345 | F30: 2178 | G30: 1653 | H30: 2576 | I30: 1612 | J30: 3270 | K30: 4635 | L30: 5376 | M30: 11561 | N30: 12679
B31: Investments | C31: 3019 | D31: 3445 | E31: 11785 | F31: 11873 | G31: 12429 | H31: 13542 | I31: 14535 | J31: 13149 | K31: 14160 | L31: 16670 | M31: 16316 | N31: 16316
B33: Other Assets -
B34: Inventories | C34: 2073 | D34: 1844 | E34: 1373 | F34: 1600 | G34: 1623 | H34: 1706 | I34: 1752 | J34: 1886 | K34: 4232 | L34: 3943 | M34: 4420 | N34: 4572
B35: Trade receivables | C35: 4543 | D35: 5564 | E35: 3540 | F35: 3832 | G35: 2789 | H35: 4445 | I35: 4426 | J35: 5200 | K35: 5980 | L35: 6952 | M35: 7402 | N35: 5710
B36: Cash Equivalents | C36: 1555 | D36: 1483 | E36: 663 | F36: 954 | G36: 1186 | H36: 787 | I36: 2094 | J36: 5871 | K36: 6641 | L36: 11207 | M36: 9152 | N36: 11751
B37: Loans n Advances | C37: 579 | D37: 400 | E37: 291 | F37: 395 | G37: 490 | H37: 503 | I37: 552 | J37: 609 | K37: 887 | L37: 1079 | M37: 1134 | N37: 994
B38: Other asset items | C38: 12832 | D38: 14400 | E38: 14644 | F38: 15402 | G38: 17066 | H38: 16209 | I38: 17037 | J38: 16491 | K38: 18627 | L38: 21123 | M38: 21861 | N38: 25797
B39: Average Trade Recivable | C39: =C35 -> 4543 | D39: =(D35+C35)/2 -> 5053.5 | E39: =(E35+D35)/2 -> 4552 | F39: =(F35+E35)/2 -> 3686 | G39: =(G35+F35)/2 -> 3310.5 | H39: =(H35+G35)/2 -> 3617 | I39: =(I35+H35)/2 -> 4435.5 | J39: =(J35+I35)/2 -> 4813 | K39: =(K35+J35)/2 -> 5590 | ... N39: =(N35+M35)/2 -> 6556
B40: Total Assets | C40: 30539 | D40: 33561 | E40: 34615 | F40: 40832 | G40: 36502 | H40: 38135 | I40: 37616 | J40: 44456 | K40: 47153 | L40: 48173 | M40: 50489 | N40: 52645
B41: Average Total Asset | C41: =C40 -> 30539 | D41: =(D40+C40)/2 -> 32050 | E41: =(E40+D40)/2 -> 34088 | F41: =(F40+E40)/2 -> 37723.5 | G41: =(G40+F40)/2 -> 38667 | H41: =(H40+G40)/2 -> 37318.5 | I41: =(I40+H40)/2 -> 37875.5 | J41: =(J40+I40)/2 -> 41036 | K41: =(K40+J40)/2 -> 45804.5 | ... N41: =(N40+M40)/2 -> 51567
B42: Average Inventory | C42: =C34 -> 2073 | D42: =(D34+C34)/2 -> 1958.5 | E42: =(E34+D34)/2 -> 1608.5 | F42: =(F34+E34)/2 -> 1486.5 | G42: =(G34+F34)/2 -> 1611.5 | H42: =(H34+G34)/2 -> 1664.5 | I42: =(I34+H34)/2 -> 1729 | J42: =(J34+I34)/2 -> 1819 | K42: =(K34+J34)/2 -> 3059 | ... N42: =(N34+M34)/2 -> 4496

Sheet Growth
B1: To find growth of the firm we will use reinvestment rate and Return on capital | M1: Assets Purchased | N1: -2226 | O1: -3336 | P1: -7268 | Q1: -7656 | R1: -13241 | S1: -17273
M2: Assets Sold | N2: 36 | O2: 1549 | P2: 35 | Q2: 50 | R2: 146 | S2: 235
B4: Calculation of ROC | E4: 43525 | F4: 43891 | G4: 44256 | H4: 44621 | I4: 44986 | J4: 45352 | K4: 45717
B6: Current Asset
B7: Inventories | E7: ='Data_sheet for growth'!H34 -> 1706 | F7: ='Data_sheet for growth'!I34 -> 1752 | G7: ='Data_sheet for growth'!J34 -> 1886 | H7: ='Data_sheet for growth'!K34 -> 4232 | I7: ='Data_sheet for growth'!L34 -> 3943 | J7: ='Data_sheet for growth'!M34 -> 4420 | K7: ='Data_sheet for growth'!N34 -> 4572
B8: Trade receivables | E8: ='Data_sheet for growth'!H35 -> 4445 | F8: ='Data_sheet for growth'!I35 -> 4426 | G8: ='Data_sheet for growth'!J35 -> 5200 | H8: ='Data_sheet for growth'!K35 -> 5980 | I8: ='Data_sheet for growth'!L35 -> 6952 | J8: ='Data_sheet for growth'!M35 -> 7402 | K8: ='Data_sheet for growth'!N35 -> 5710
B9: Loans n Advances | E9: ='Data_sheet for growth'!H37 -> 503 | F9: ='Data_sheet for growth'!I37 -> 552 | G9: ='Data_sheet for growth'!J37 -> 609 | H9: ='Data_sheet for growth'!K37 -> 887 | I9: ='Data_sheet for growth'!L37 -> 1079 | J9: ='Data_sheet for growth'!M37 -> 1134 | K9: ='Data_sheet for growth'!N37 -> 994
