Workbook

Sheet INDEX
C1: INDEX | F1: COMPANY
C4: Sr No. | D4: Particulars | E4: Link to Sheet
C5: 1 | D5: Balance Sheet | E5: Balance Sheet
C6: 2 | D6: Profit & Loss | E6: Profit and Loss Statement
C7: 3 | D7: Cash Flow Statement | E7: Cash Flow Statement
C8: 4 | D8: Share Holding Pattern | E8: Share Holding Pattern
C9: 5 | D9: Calculation of Financial Ratio | E9: Financial ratio
C10: 6 | D10: Du Pont Analysis | E10: Du Pont
C11: 7 | D11: Calculation of Market return | E11: Market return
C12: 8 | D12: Beta calculation using Historical return | E12: Beta Calculation
C13: 9 | D13: Bottom up Beta Calculation | E13: Peer Comparison & COE
C14: 10 | D14: Calculation of Ke | E14: Peer Comparison & COE
C15: 11 | D15: Calculation of Kd | E15: COD
C16: 12 | D16: WACC | E16: WACC
... C21: 17 | D21: References | E21: References

Sheet Balance Sheet
B2: Column 1 | C2: Mar-14 | D2: Mar-15 | E2: Mar-16 | F2: Mar-17 | G2: Mar-18 | H2: Mar-19 | I2: Mar-20 | J2: Mar-21 | K2: Mar-22 | L2: Mar-23 | M2: Mar-24 | N2: Mar-25
B3: Equity Capital | C3: 472 | D3: 472 | E3: 481 | F3: 481 | G3: 481 | H3: 481 | I3: 481 | J3: 481 | K3: 481 | L3: 481 | M3: 481 | N3: 504
B4: Reserves | C4: 5704 | D4: 6436 | E4: 5978 | F4: 6404 | G4: 7212 | H4: 8456 | I4: 8707 | J4: 9771 | K4: 9485 | L4: 10539 | M4: 11558 | N4: 16952
B5: Borrowings - | C5: 6149 | D5: 5629 | E5: 8392 | F5: 8666 | G5: 9216 | H5: 9116 | I5: 8340 | J5: 7200 | K5: 7908 | L5: 8430 | M5: 9744 | N5: 6388
B6: Long term Borrowings | C6: 5594 | D6: 5019 | E6: 8096 | F6: 8112 | G6: 8502 | H6: 8033 | I6: 7296 | J6: 6071 | K6: 6120 | L6: 7045 | M6: 8285 | N6: 5236
B7: Short term Borrowings | C7: 0 | D7: 0 | E7: 0 | F7: 77 | G7: 0 | H7: 300 | I7: 0 | J7: 1093 | K7: 1746 | L7: 1345 | M7: 1418 | N7: 1119
B8: Lease Liabilities | C8: 0 | D8: 0 | E8: 0 | F8: 0 | G8: 0 | H8: 0 | I8: 38 | J8: 36 | K8: 42 | L8: 41 | M8: 41 | N8: 32
B9: Other Borrowings | C9: 555 | D9: 610 | E9: 296 | F9: 478 | G9: 714 | H9: 783 | I9: 1006 | J9: 0 | K9: 0 | L9: 0 | M9: 0 | N9: 0
B10: Other Liabilities - | C10: 2969 | D10: 3318 | E10: 4650 | F10: 5064 | G10: 5193 | H10: 5772 | I10: 5352 | J10: 5327 | K10: 5730 | L10: 6538 | M10: 7409 | N10: 7815
B11: Trade Payables | C11: 633 | D11: 621 | E11: 735 | F11: 733 | G11: 657 | H11: 804 | I11: 1027 | J11: 971 | K11: 1108 | L11: 1081 | M11: 1090 | N11: 1370
B12: Advance from Customers | C12: 58 | D12: 72 | E12: 68 | F12: 63 | G12: 59 | H12: 67 | I12: 82 | J12: 84 | K12: 99 | L12: 94 | M12: 97 | N12: 97
B13: Other liability items | C13: 2277 | D13: 2625 | E13: 3847 | F13: 4268 | G13: 4477 | H13: 4901 | I13: 4243 | J13: 4271 | K13: 4523 | L13: 5363 | M13: 6221 | N13: 6445
B14: Total Liabilities | C14: 15294 | D14: 15856 | E14: 19501 | F14: 20615 | G14: 22102 | H14: 23825 | I14: 22880 | J14: 22778 | K14: 23605 | L14: 25988 | M14: 29191 | N14: 31659
... B34: Other asset items | C34: 603 | D34: 613 | E34: 1232 | F34: 1230 | G34: 1382 | H34: 2913 | I34: 3316 | J34: 3546 | K34: 3542 | L34: 4457 | M34: 6559 | N34: 4415
B35: Average Trade receivables | C35: 804 | D35: =(D31+C31)/2 -> 829 | E35: =(E31+D31)/2 -> 961.5 | F35: =(F31+E31)/2 -> 1009 | G35: =(G31+F31)/2 -> 1046.5 | H35: =(H31+G31)/2 -> 1147.5 | I35: =(I31+H31)/2 -> 1176 | J35: =(J31+I31)/2 -> 1228.5 | K35: =(K31+J31)/2 -> 1320 | ... N35: =(N31+M31)/2 -> 1628.5
B36: Total Assets | C36: 15294 | D36: 15856 | E36: 19501 | F36: 20615 | G36: 22102 | H36: 23825 | I36: 22880 | J36: 22778 | K36: 23605 | L36: 25988 | M36: 29191 | N36: 31659
B37: Average Total Asset | C37: 19126 | D37: =(D36+C36)/2 -> 15575 | E37: =(E36+D36)/2 -> 17678.5 | F37: =(F36+E36)/2 -> 20058 | G37: =(G36+F36)/2 -> 21358.5 | H37: =(H36+G36)/2 -> 22963.5 | I37: =(I36+H36)/2 -> 23352.5 | J37: =(J36+I36)/2 -> 22829 | K37: =(K36+J36)/2 -> 23191.5 | ... N37: =(N36+M36)/2 -> 30425
B38: Average Inventory | C38: =C30 -> 283 | D38: =(D30+C30)/2 -> 268 | E38: =(E30+D30)/2 -> 336.5 | F38: =(F30+E30)/2 -> 394.5 | G38: =(G30+F30)/2 -> 411.5 | H38: =(H30+G30)/2 -> 540.5 | I38: =(I30+H30)/2 -> 612.5 | J38: =(J30+I30)/2 -> 492 | K38: =(K30+J30)/2 -> 412 | ... N38: =(N30+M30)/2 -> 627.5
B40: *Due to the unavailability of data for Mar-25, the values for the item highlighted in yellow have been assumed to be the same as the previous year’s figures, in order to maintain continuity in the valuation analysis

Sheet Profit and Loss Statement
B2: Column 1 | C2: Mar-14 | D2: Mar-15 | E2: Mar-16 | F2: Mar-17 | G2: Mar-18 | H2: Mar-19 | I2: Mar-20 | J2: Mar-21 | K2: Mar-22 | L2: Mar-23 | M2: Mar-24 | N2: Mar-25
B3: Sales - | C3: 8536 | D3: 10200 | E3: 11626 | F3: 9921 | G3: 11449 | H3: 12978 | I3: 13442 | J3: 11777 | K3: 13716 | L3: 18836 | M3: 19957 | N3: 21913
B4: Sales Growth % | C4: 0.0551 | D4: 0.195 | E4: 0.1398 | F4: -0.1467 | G4: 0.154 | H4: 0.1335 | I4: 0.0358 | J4: -0.1239 | K4: 0.1647 | L4: 0.3733 | M4: 0.0595 | N4: 0.098
B5: Expenses - | C5: 7302 | D5: 8143 | E5: 8675 | F5: 7481 | G5: 8368 | H5: 9918 | I5: 10003 | J5: 8533 | K5: 10356 | L5: 14582 | M5: 16070 | N5: 17555
B6: Manufacturing Cost % | C6: 0.8 | D6: 0.75 | E6: 0.69 | F6: 0.7 | G6: 0.67 | H6: 0.71 | I6: 0.67 | J6: 0.65 | K6: 0.7 | L6: 0.73 | M6: 0.76 | N6: 0.66
B7: Employee Cost % | C7: 0.04 | D7: 0.04 | E7: 0.04 | F7: 0.06 | G7: 0.06 | H7: 0.05 | I7: 0.05 | J7: 0.06 | K7: 0.05 | L7: 0.04 | M7: 0.04 | N7: 0.03
B8: Other Cost % | C8: 0.01 | D8: 0.01 | E8: 0.01 | F8: 0 | G8: 0 | H8: 0 | I8: 0.02 | J8: 0.02 | K8: 0.01 | L8: 0.01 | M8: 0.01 | N8: 0.06
B9: Operating Profit | C9: 1234 | D9: 2057 | E9: 2951 | F9: 2440 | G9: 3080 | H9: 3060 | I9: 3439 | J9: 3244 | K9: 3359 | L9: 4254 | M9: 3887 | N9: 4357
B10: OPM % | C10: 0.14 | D10: 0.2 | E10: 0.25 | F10: 0.25 | G10: 0.27 | H10: 0.24 | I10: 0.26 | J10: 0.28 | K10: 0.24 | L10: 0.23 | M10: 0.19 | N10: 0.2
B11: Other Income - | C11: 224 | D11: 306 | E11: 337 | F11: 180 | G11: 246 | H11: 244 | I11: -771 | J11: 238 | K11: -1030 | L11: 405 | M11: 464 | N11: 687
B12: Exceptional items | C12: 30 | D12: 9 | E12: 54 | F12: 49 | G12: 75 | H12: 31 | I12: -964 | J12: 21 | K12: -1243 | L12: 96 | M12: 109 | N12: 0
B13: Other income normal | C13: 195 | D13: 297 | E13: 283 | F13: 131 | G13: 171 | H13: 213 | I13: 193 | J13: 217 | K13: 213 | L13: 309 | M13: 355 | N13: 687
B14: Interest | C14: 677 | D14: 706 | E14: 1116 | F14: 1047 | G14: 840 | H14: 892 | I14: 892 | J14: 719 | K14: 582 | L14: 668 | M14: 781 | N14: 874
... B24: Dividend Payout % | C24: 0.25 | D24: 0.1 | E24: 0.24 | F24: 0.24 | G24: 0.26 | H24: 0.27 | I24: 0.45 | J24: 0.4 | K24: 1.06 | L24: 0.59 | M24: 0.43 | N24: 0.34

Sheet Cash Flow Statement
B2: Column 1 | C2: Mar-14 | D2: Mar-15 | E2: Mar-16 | F2: Mar-17 | G2: Mar-18 | H2: Mar-19 | I2: Mar-20 | J2: Mar-21 | K2: Mar-22 | L2: Mar-23 | M2: Mar-24 | N2: Mar-25
B3: Cash from Operating Activity - | C3: 1272 | D3: 1640 | E3: 2502 | F3: 2312 | G3: 2803 | H3: 2334 | I3: 3469 | J3: 2670 | K3: 2981 | L3: 3118 | M3: 3414 | N3: 4278
B4: Profit from operations | C4: 1252 | D4: 1931 | E4: 2870 | F4: 2420 | G4: 3119 | H4: 3026 | I4: 3624 | J4: 3267 | K4: 3292 | L4: 4244 | M4: 3763 | N4: 4379
B5: Receivables | C5: -68 | D5: -74 | E5: -97 | F5: 66 | G5: -165 | H5: -66 | I5: -75 | J5: -322 | K5: -94 | L5: -135 | M5: -55 | N5: -163
B6: Inventory | C6: -39 | D6: 30 | E6: -103 | F6: 51 | G6: -86 | H6: -172 | I6: 29 | J6: 150 | K6: -52 | L6: -208 | M6: 179 | N6: -143
B7: Payables | C7: 45 | D7: -12 | E7: 235 | F7: -169 | G7: -33 | H7: 174 | I7: 204 | J7: -42 | K7: 198 | L7: 40 | M7: 187 | N7: 337
B8: Loans Advances | C8: 7 | D8: -554 | E8: 0 | F8: -19 | G8: -14 | H8: 1 | I8: -1 | J8: 0 | K8: 0 | L8: 0 | M8: 0 | N8: 0
B9: Other WC items | C9: 94 | D9: 434 | E9: -92 | F9: 66 | G9: 294 | H9: -350 | I9: -21 | J9: -130 | K9: -134 | L9: -357 | M9: -223 | N9: 27
B10: Working capital changes | C10: 39 | D10: -176 | E10: -57 | F10: -5 | G10: -4 | H10: -413 | I10: 135 | J10: -343 | K10: -82 | L10: -660 | M10: 89 | N10: 59
B11: Direct taxes | C11: -19 | D11: -115 | E11: -312 | F11: -104 | G11: -311 | H11: -279 | I11: -290 | J11: -254 | K11: -229 | L11: -466 | M11: -438 | N11: -159
B12: Cash from Investing Activity - | C12: -1225 | D12: -357 | E12: -913 | F12: -2111 | G12: -2493 | H12: -1231 | I12: -1096 | J12: -595 | K12: -2512 | L12: -2137 | M12: -3187 | N12: -2880
B13: Fixed assets purchased | C13: -626 | D13: -541 | E13: -1305 | F13: -2531 | G13: -1724 | H13: -1583 | I13: -680 | J13: -1281 | K13: -1541 | L13: -1909 | M13: -1754 | N13: -1457
B14: Fixed assets sold | C14: 4 | D14: 12 | E14: 10 | F14: 9 | G14: 61 | H14: 101 | I14: 10 | J14: 7 | K14: 47 | L14: 66 | M14: 56 | N14: 23
... B19: Invest in subsidiaries | C19: -724 | D19: -80 | E19: 0 | F19: 0 | G19: 0 | H19: -221 | I19: -2 | J19: 0 | K19: -606 | L19: -175 | M19: -90 | N19: -1175
B20: Loans to Subsidiaries
B21: Investment in group cos | C21: 0 | D21: 0 | E21: 0 | F21: 0 | G21: 0 | H21: 0 | I21: 0 | J21: 0 | K21: 0 | L21: 0 | M21: 0 | N21: 0
B22: Redemp n Canc of Shares | C22: 0 | D22: 0 | E22: 0 | F22: 0 | G22: 0 | H22: 0 | I22: 0 | J22: 0 | K22: 0 | L22: 0 | M22: 0 | N22: 1451
B23: Acquisition of companies
B24: nter corporate deposits | C24: 0 | D24: 0 | E24: 0 | F24: 0 | G24: 0 | H24: 0 | I24: 25 | J24: -100 | K24: 113 | L24: 267 | M24: 0 | N24: 0
B25: Other investing items | C25: -27 | D25: 102 | E25: 238 | F25: 402 | G25: -899 | H25: 169 | I25: -771 | J25: 272 | K25: -140 | L25: -311 | M25: -1511 | N25: -2324
B26: Cash from Financing Activity - | C26: 532 | D26: -1161 | E26: -2126 | F26: -640 | G26: -278 | H26: -1123 | I26: -2408 | J26: -2059 | K26: -402 | L26: -1004 | M26: -101 | N26: -1438
B27: Proceeds from shares | C27: 0 | D27: 0 | E27: 0 | F27: 0 | G27: 0 | H27: 0 | I27: 0 | J27: 0 | K27: 0 | L27: 0 | M27: 0 | N27: 3440
B28: Proceeds from borrowings | C28: 1666 | D28: 37 | E28: 8633 | F28: 1649 | G28: 988 | H28: 1517 | I28: 2020 | J28: 1000 | K28: 1803 | L28: 2700 | M28: 3970 | N28: 1164
B29: Repayment of borrowings | C29: -465 | D29: -563 | E29: -9414 | F29: -1380 | G29: -436 | H29: -1622 | I29: -2842 | J29: -2141 | K29: -1100 | L29: -2177 | M29: -2662 | N29: -4486
B30: Interest paid fin | C30: -676 | D30: -715 | E30: -1167 | F30: -1022 | G30: -820 | H30: -896 | I30: -807 | J30: -763 | K30: -600 | L30: -679 | M30: -799 | N30: -885
B31: Dividends paid | C31: -94 | D31: -24 | E31: -284 | F31: 0 | G31: -106 | H31: -288 | I31: -959 | J31: -264 | K31: -697 | L31: -1057 | M31: -769 | N31: -898
B32: Financial liabilities | C32: 0 | D32: 0 | E32: 0 | F32: 0 | G32: 0 | H32: 0 | I32: -6 | J32: -7 | K32: -9 | L32: -8 | M32: -20 | N32: -17
B33: Other financing items | C33: 102 | D33: 103 | E33: 107 | F33: 114 | G33: 96 | H33: 166 | I33: 186 | J33: 116 | K33: 200 | L33: 217 | M33: 179 | N33: 243
B34: Net Cash Flow | C34: 579 | D34: 122 | E34: -537 | F34: -439 | G34: 32 | H34: -20 | I34: -35 | J34: 16 | K34: 66 | L34: -24 | M34: 126 | N34: -41

Sheet Share Holding Pattern 
B2: Column 1 | C2: Mar-17 | D2: Mar-18 | E2: Mar-19 | F2: Mar-20 | G2: Mar-21 | H2: Mar-22 | I2: Mar-23 | J2: Mar-24 | K2: Mar-25
B3: Promoters - | C3: 0.5357 | D3: 0.5357 | E3: 0.5357 | F3: 0.5357 | G3: 0.5357 | H3: 0.5357 | I3: 0.5356 | J3: 0.5356 | K3: 0.5109
B4: Torrent Investments Private Limited | H4: 53.56 | I4: 53.56 | J4: 53.56
B5: Torrent Private Limited | C5: 53.56 | D5: 53.56 | E5: 53.56 | F5: 53.56
B6: Torrent Investments Private Limited (Formerly know... | G6: 53.56
B7: Torrent Investments Limited (Formerly known as Tor... | K7: 51.09
B8: Samir Uttamlal Mehta | C8: 0 | D8: 0 | E8: 0 | F8: 0 | G8: 0 | H8: 0 | I8: 0 | J8: 0 | K8: 0
B9: Sudhir Uttamlal Mehta | C9: 0 | D9: 0 | E9: 0 | F9: 0 | G9: 0 | H9: 0 | I9: 0 | J9: 0 | K9: 0
B10: Jinal Sudhir Mehta | C10: 0 | D10: 0 | E10: 0 | F10: 0 | G10: 0 | H10: 0 | I10: 0 | J10: 0 | K10: 0
B11: Mehta Family Trust 4 | J11: 0 | K11: 0
B12: Mehta Family Trust 3 | J12: 0 | K12: 0
B13: Mehta Family Trust 2 | J13: 0 | K13: 0
B14: Mehta Family Trust 1 | J14: 0 | K14: 0
B15: FIIs - | C15: 0.0677 | D15: 0.0587 | E15: 0.0781 | F15: 0.0875 | G15: 0.0845 | H15: 0.0686 | I15: 0.063 | J15: 0.064 | K15: 0.0943
B16: DIIs - | C16: 0.1631 | D16: 0.1789 | E16: 0.1594 | F16: 0.181 | G16: 0.1877 | H16: 0.2091 | I16: 0.2163 | J16: 0.2147 | K16: 0.219
B17: SBI Mutual Funds | K17: 7.95
B18: Axis Elss Tax Saver Fund | J18: 7.18
B19: Axis Mutual Fund Trustee Limited A/C Axis Mutual F... | C19: 2.89 | D19: 4.71 | E19: 6.4 | F19: 6.15 | G19: 7.82 | H19: 8.5 | I19: 8.67
B20: SBI Long Term Equity Fund | J20: 6.21
B21: Life Insurance Corporation Of India | C21: 6.22 | D21: 5.92 | E21: 3.11 | H21: 4.55 | I21: 4.1 | J21: 3.49 | K21: 2.82
B22: Sbi Focused Equity Fund | F22: 3.05 | G22: 4.64 | H22: 3.62 | I22: 5.26
B23: Axis Mutual Funds | K23: 3.92
B24: Uti-Mid Cap Fund | D24: 2.23 | E24: 2.44
B25: Uti- Value Opportunities Fund | F25: 1.84
B26: Reliance Capital Trustee Co Ltd.A/C Reliance Multi Cap Fund | E26: 1.66
B27: Hdfc Life Insurance Company Limited | F27: 1.8 | G27: 1.78 | H27: 1.05 | I27: 1.12 | J27: 1.37
B28: General Insurance Corporation Of India | C28: 1.54 | D28: 1.27
B29: The New India Assurance Company Limited | C29: 1.59 | D29: 1.06
B30: Franklin India Prima Fund | F30: 1.18
B31: Reliance Capital Trustee Co. Ltd. A/C Reliance Div... | D31: 1.13
B32: Government + | C32: 0.0147 | D32: 0.0173 | E32: 0.0147 | F32: 0.0147 | G32: 0.0147 | H32: 0.0147 | I32: 0.0147 | J32: 0.0147 | K32: 0.0835
B33: Public + | C33: 0.2188 | D33: 0.2094 | E33: 0.2121 | F33: 0.1811 | G33: 0.1775 | H33: 0.172 | I33: 0.1702 | J33: 0.171 | K33: 0.0925
B34: No. of Shareholders | C34: 1,18,491 | D34: 1,23,399 | E34: 1,17,467 | F34: 1,11,862 | G34: 1,12,348 | H34: 1,34,002 | I34: 1,25,793 | J34: 1,40,153 | K34: 1,65,189

Sheet Financial ratio 
C1: 41699 | D1: 42064 | E1: 42430 | F1: 42795 | G1: 43160 | H1: 43525 | I1: 43891 | J1: 44256 | K1: 44621 | L1: 44986 | M1: 45352 | N1: 45717 | O1: Ideal Value | P1: Formula Used | Q1: Average | S1: Analysis
B2: Profitability Ratios
B3: Net Profit Ratio | C3: ='Profit and Loss Statement'!C18/'Profit and Loss Statement'!C3 -> 0.011129335 | D3: ='Profit and Loss Statement'!D18/'Profit and Loss Statement'!D3 -> 0.072745098 | E3: ='Profit and Loss Statement'!E18/'Profit and Loss Statement'!E3 -> 0.077326682 | F3: ='Profit and Loss Statement'!F18/'Profit and Loss Statement'!F3 -> 0.043543998 | G3: ='Profit and Loss Statement'!G18/'Profit and Loss Statement'!G3 -> 0.080531051 | H3: ='Profit and Loss Statement'!H18/'Profit and Loss Statement'!H3 -> 0.068500539 | I3: ='Profit and Loss Statement'!I18/'Profit and Loss Statement'!I3 -> 0.09209939 | J3: ='Profit and Loss Statement'!J18/'Profit and Loss Statement'!J3 -> 0.11250743 | ... N3: ='Profit and Loss Statement'!N18/'Profit and Loss Statement'!N3 -> 0.13010542 | O3: 13.72 | P3: Net Profit / Sales | Q3: =AVERAGE(C3:N3) -> 0.076681311 | S3: Improving long-term trend with recent highs close to the ideal (13.72%); average (7.67%) surpassed in most years post-2020, indicating strong profitability recovery.
C4: Bad | D4: Good | E4: Good | F4: Bad | G4: Good | H4: Good | I4: Good | J4: Excellent | K4: Bad | L4: Excellent | M4: Good | N4: Excellent
B5: Operating Margin | C5: ='Profit and Loss Statement'!C10 -> 0.14 | D5: ='Profit and Loss Statement'!D10 -> 0.2 | E5: ='Profit and Loss Statement'!E10 -> 0.25 | F5: ='Profit and Loss Statement'!F10 -> 0.25 | G5: ='Profit and Loss Statement'!G10 -> 0.27 | H5: ='Profit and Loss Statement'!H10 -> 0.24 | I5: ='Profit and Loss Statement'!I10 -> 0.26 | J5: ='Profit and Loss Statement'!J10 -> 0.28 | ... N5: ='Profit and Loss Statement'!N10 -> 0.2 | O5: 0.2973 | P5: - | Q5: =AVERAGE(C5:N5) -> 0.22916667 | S5: Consistently above average (22.92%) from FY16 onward, though still below the ideal 30%, showing healthy but improvable operational efficiency.
C6: Bad | D6: Good | E6: Good | F6: Good | G6: Good | H6: Good | I6: Good | J6: Good | K6: Good | L6: Good | M6: Good | N6: Good
B7: Return on Assets | C7: ='Profit and Loss Statement'!C18/'Balance Sheet'!C36 -> 0.0062115862 | D7: ='Profit and Loss Statement'!D18/'Balance Sheet'!D36 -> 0.046796165 | E7: ='Profit and Loss Statement'!E18/'Balance Sheet'!E36 -> 0.0461002 | F7: ='Profit and Loss Statement'!F18/'Balance Sheet'!F36 -> 0.020955615 | G7: ='Profit and Loss Statement'!G18/'Balance Sheet'!G36 -> 0.041715682 | H7: ='Profit and Loss Statement'!H18/'Balance Sheet'!H36 -> 0.037313746 | I7: ='Profit and Loss Statement'!I18/'Balance Sheet'!I36 -> 0.054108392 | J7: ='Profit and Loss Statement'!J18/'Balance Sheet'!J36 -> 0.058170164 | ... N7: ='Profit and Loss Statement'!N18/'Balance Sheet'!N36 -> 0.090053381 | O7: 0.0262 | P7: Net Profit / Total Assets | Q7: =AVERAGE(C7:N7) -> 0.046779075 | S7: ROA showed volatility, but consistently outperformed both the low ideal (2.62%) and the average (4.68%) post-2020, reflecting enhanced asset utilization.
C8: Bad | D8: Good | E8: Good | F8: Bad | G8: Good | H8: Good | I8: Excellent | J8: Excellent | K8: Bad | L8: Excellent | M8: Excellent | N8: Excellent
B9: Return on Capital Employed | C9: ='Profit and Loss Statement'!C9/('Balance Sheet'!C4+'Balance Sheet'!C3+'Balance Sheet'!C5) -> 0.1001217 | D9: ='Profit and Loss Statement'!D9/('Balance Sheet'!D4+'Balance Sheet'!D3+'Balance Sheet'!D5) -> 0.16407434 | E9: ='Profit and Loss Statement'!E9/('Balance Sheet'!E4+'Balance Sheet'!E3+'Balance Sheet'!E5) -> 0.19870716 | F9: ='Profit and Loss Statement'!F9/('Balance Sheet'!F4+'Balance Sheet'!F3+'Balance Sheet'!F5) -> 0.15690309 | G9: ='Profit and Loss Statement'!G9/('Balance Sheet'!G4+'Balance Sheet'!G3+'Balance Sheet'!G5) -> 0.18215152 | H9: ='Profit and Loss Statement'!H9/('Balance Sheet'!H4+'Balance Sheet'!H3+'Balance Sheet'!H5) -> 0.16950091 | I9: ='Profit and Loss Statement'!I9/('Balance Sheet'!I4+'Balance Sheet'!I3+'Balance Sheet'!I5) -> 0.19620037 | J9: ='Profit and Loss Statement'!J9/('Balance Sheet'!J4+'Balance Sheet'!J3+'Balance Sheet'!J5) -> 0.18588127 | ... N9: ='Profit and Loss Statement'!N9/('Balance Sheet'!N4+'Balance Sheet'!N3+'Balance Sheet'!N5) -> 0.18272941 | O9: 0.0869 | P9: Operating profit / Capital employed | Q9: =AVERAGE(C9:N9) -> 0.17677941 | S9: Strong and stable upward trend, consistently above both the ideal (8.69%) and average (17.68%), indicating highly efficient capital use.
C10: Good | D10: Good | E10: Excellent | F10: Good | G10: Excellent | H10: Good | I10: Excellent | J10: Excellent | K10: Excellent | L10: Excellent | M10: Good | N10: Excellent
B11: Return on Equity | C11: ='Profit and Loss Statement'!C18/('Balance Sheet'!C3+'Balance Sheet'!C4) -> 0.015382124 | D11: ='Profit and Loss Statement'!D18/('Balance Sheet'!D3+'Balance Sheet'!D4) -> 0.1074117 | E11: ='Profit and Loss Statement'!E18/('Balance Sheet'!E3+'Balance Sheet'!E4) -> 0.13918563 | F11: ='Profit and Loss Statement'!F18/('Balance Sheet'!F3+'Balance Sheet'!F4) -> 0.062745098 | G11: ='Profit and Loss Statement'!G18/('Balance Sheet'!G3+'Balance Sheet'!G4) -> 0.11984921 | H11: ='Profit and Loss Statement'!H18/('Balance Sheet'!H3+'Balance Sheet'!H4) -> 0.099474096 | I11: ='Profit and Loss Statement'!I18/('Balance Sheet'!I3+'Balance Sheet'!I4) -> 0.13474097 | J11: ='Profit and Loss Statement'!J18/('Balance Sheet'!J3+'Balance Sheet'!J4) -> 0.12924307 | ... N11: ='Profit and Loss Statement'!N18/('Balance Sheet'!N3+'Balance Sheet'!N4) -> 0.16332493 | O11: 0.0746 | P11: Net Profit / Total Equity | Q11: =AVERAGE(C11:N11) -> 0.11273085 | S11: Fluctuated but showed a clear upward trend post-2020, exceeding both the ideal (7.46%) and average (11.27%) in most years, indicating increasing shareholder value.
C12: Bad | D12: Good | E12: Excellent | F12: Bad | G12: Good | H12: Good | I12: Excellent | J12: Good | K12: Bad | L12: Excellent | M12: Excellent | N12: Excellent
B13: Dividend Payout Ratio | C13: ='Profit and Loss Statement'!C24 -> 0.25 | D13: ='Profit and Loss Statement'!D24 -> 0.1 | E13: ='Profit and Loss Statement'!E24 -> 0.24 | F13: ='Profit and Loss Statement'!F24 -> 0.24 | G13: ='Profit and Loss Statement'!G24 -> 0.26 | H13: ='Profit and Loss Statement'!H24 -> 0.27 | I13: ='Profit and Loss Statement'!I24 -> 0.45 | J13: ='Profit and Loss Statement'!J24 -> 0.4 | ... N13: ='Profit and Loss Statement'!N24 -> 0.34 | O13: 0 | P13: - | Q13: =AVERAGE(C13:N13) -> 0.38583333 | S13: Initially well-aligned with an ideal low-payout strategy, but post-2020, payout ratios exceed sustainable thresholds, risking capital reinvestment and debt servicing needs.
C14: Excellent | D14: Excellent | E14: Excellent | F14: Excellent | G14: Excellent | H14: Excellent | I14: Bad | J14: Bad | K14: Bad | L14: Bad | M14: Bad | N14: Good
B15: Price to Earnings Ratio | C15: =C17/C11 -> 46.807579 | D15: =D17/D11 -> 10.33407 | E15: =E17/E11 -> 36.49802 | F15: =F17/F11 -> 37.93125 | G15: =G17/G11 -> 39.049067 | H15: =H17/H11 -> 103.64507 | I15: =I17/I11 -> 98.856349 | J15: =J17/J11 -> 15.397343 | ... N15: =N17/N11 -> 26.266657 | O15: 34.8 | P15: (MV/BV)/ROE | Q15: =AVERAGE(C15:N15) -> 43.353229 | S15: Highly volatile, often deviating from both ideal (34.8) and average (70.5), reflecting market overreaction cycles and inconsistent earnings multiples.
C16: Good | D16: Good | E16: Good | F16: Good | G16: Good | H16: Bad | I16: Bad | J16: Good | K16: Bad | L16: Good | M16: Bad | N16: Good
B17: Market Value/Book Value | C17: 0.72 | D17: 1.11 | E17: 5.08 | F17: 2.38 | G17: 4.68 | H17: 10.31 | I17: 13.32 | J17: 1.99 | K17: 2.37 | L17: 2.22 | M17: 5.409 | N17: 4.29 | O17: 2.41 | P17: - | Q17: =AVERAGE(C17:N17) -> 4.4899167 | S17: Long-term trend moved from deep undervaluation to volatile overvaluation, averaging above the ideal (2.41), indicating fluctuating market sentiment
C18: Bad | D18: Bad | E18: Good | F18: Good | G18: Good | H18: Excellent | I18: Excellent | J18: Bad | K18: Good | L18: Good | M18: Good | N18: Good
B20: Liquidity Ratio
B21: Current Ratio | C21: =(SUM('Balance Sheet'!C30:C34))/SUM('Balance Sheet'!C11:C13) -> 1.1007412 | D21: =(SUM('Balance Sheet'!D30:D34))/SUM('Balance Sheet'!D11:D13) -> 1.1847498 | E21: =(SUM('Balance Sheet'!E30:E34))/SUM('Balance Sheet'!E11:E13) -> 0.7944086 | F21: =(SUM('Balance Sheet'!F30:F34))/SUM('Balance Sheet'!F11:F13) -> 0.58056872 | G21: =(SUM('Balance Sheet'!G30:G34))/SUM('Balance Sheet'!G11:G13) -> 0.75389948 | H21: =(SUM('Balance Sheet'!H30:H34))/SUM('Balance Sheet'!H11:H13) -> 0.91683992 | I21: =(SUM('Balance Sheet'!I30:I34))/SUM('Balance Sheet'!I11:I13) -> 1.0276532 | J21: =(SUM('Balance Sheet'!J30:J34))/SUM('Balance Sheet'!J11:J13) -> 1.0473151 | ... N21: =(SUM('Balance Sheet'!N30:N34))/SUM('Balance Sheet'!N11:N13) -> 1.6171638 | O21: 1.27 | P21: Current Assets/ Current Liabilities | Q21: =AVERAGE(C21:N21) -> 1.0468472 | S21: Current ratio has remained around the industry average(1.27), reflecting that the comapny manages enough inventory and assets to meet up its short-term liabilities
C22: Good | D22: Good | E22: Bad | F22: Bad | G22: Bad | H22: Bad | I22: Good | J22: Good | K22: Good | L22: Good | M22: Good | N22: Excellent
B23: Quick Ratio | C23: =(SUM('Balance Sheet'!C30:C34)-'Balance Sheet'!C30)/SUM('Balance Sheet'!C11:C13) -> 1.0053908 | D23: =(SUM('Balance Sheet'!D30:D34)-'Balance Sheet'!D30)/SUM('Balance Sheet'!D11:D13) -> 1.1084991 | E23: =(SUM('Balance Sheet'!E30:E34)-'Balance Sheet'!E30)/SUM('Balance Sheet'!E11:E13) -> 0.70408602 | F23: =(SUM('Balance Sheet'!F30:F34)-'Balance Sheet'!F30)/SUM('Balance Sheet'!F11:F13) -> 0.50770142 | G23: =(SUM('Balance Sheet'!G30:G34)-'Balance Sheet'!G30)/SUM('Balance Sheet'!G11:G13) -> 0.6664741 | H23: =(SUM('Balance Sheet'!H30:H34)-'Balance Sheet'!H30)/SUM('Balance Sheet'!H11:H13) -> 0.80821206 | I23: =(SUM('Balance Sheet'!I30:I34)-'Balance Sheet'!I30)/SUM('Balance Sheet'!I11:I13) -> 0.91591928 | J23: =(SUM('Balance Sheet'!J30:J34)-'Balance Sheet'!J30)/SUM('Balance Sheet'!J11:J13) -> 0.97484041 | ... N23: =(SUM('Balance Sheet'!N30:N34)-'Balance Sheet'!N30)/SUM('Balance Sheet'!N11:N13) -> 1.5401921 | O23: 1.08 | P23: (Current Assets - Inventory)/ Current Liabilities | Q23: =AVERAGE(C23:N23) -> 0.95897433 | S23: Quick ratio follows similar trend as Current Assets, initially below industry average but after FY24 it surpassed the industry average
C24: Good | D24: Good | E24: Bad | F24: Bad | G24: Bad | H24: Bad | I24: Bad | J24: Bad | K24: Bad | L24: Bad | M24: Good | N24: Excellent
B26: Capital Structure Ratio
B27: Debt to Equity Ratio(Total debt/TE) | C27: =('Balance Sheet'!C6+'Balance Sheet'!C7)/('Balance Sheet'!C4+'Balance Sheet'!C3) -> 0.90576425 | D27: =('Balance Sheet'!D6+'Balance Sheet'!D7)/('Balance Sheet'!D4+'Balance Sheet'!D3) -> 0.72654893 | E27: =('Balance Sheet'!E6+'Balance Sheet'!E7)/('Balance Sheet'!E4+'Balance Sheet'!E3) -> 1.2534448 | F27: =('Balance Sheet'!F6+'Balance Sheet'!F7)/('Balance Sheet'!F4+'Balance Sheet'!F3) -> 1.1893972 | G27: =('Balance Sheet'!G6+'Balance Sheet'!G7)/('Balance Sheet'!G4+'Balance Sheet'!G3) -> 1.1051605 | H27: =('Balance Sheet'!H6+'Balance Sheet'!H7)/('Balance Sheet'!H4+'Balance Sheet'!H3) -> 0.9324158 | I27: =('Balance Sheet'!I6+'Balance Sheet'!I7)/('Balance Sheet'!I4+'Balance Sheet'!I3) -> 0.79407923 | J27: =('Balance Sheet'!J6+'Balance Sheet'!J7)/('Balance Sheet'!J4+'Balance Sheet'!J3) -> 0.69879048 | ... N27: =('Balance Sheet'!N6+'Balance Sheet'!N7)/('Balance Sheet'!N4+'Balance Sheet'!N3) -> 0.3640582 | O27: 0.7 | P27: Total Debt / Total Equity | Q27: =AVERAGE(C27:N27) -> 0.86052083 | S27: Debt/Equity ratio is almost around the industry average value(0.7) across the years
C28: optimal | D28: optimal | E28: optimal | F28: risky | G28: risky | H28: optimal | I28: optimal | J28: optimal | K28: optimal | L28: optimal | M28: optimal | N28: optimal
B29: Debt to Assets Ratio | C29: ='Balance Sheet'!C5/'Balance Sheet'!C36 -> 0.40205309 | D29: ='Balance Sheet'!D5/'Balance Sheet'!D36 -> 0.35500757 | E29: ='Balance Sheet'!E5/'Balance Sheet'!E36 -> 0.43033691 | F29: ='Balance Sheet'!F5/'Balance Sheet'!F36 -> 0.42037351 | G29: ='Balance Sheet'!G5/'Balance Sheet'!G36 -> 0.41697584 | H29: ='Balance Sheet'!H5/'Balance Sheet'!H36 -> 0.38262329 | I29: ='Balance Sheet'!I5/'Balance Sheet'!I36 -> 0.36451049 | J29: ='Balance Sheet'!J5/'Balance Sheet'!J36 -> 0.31609448 | ... N29: ='Balance Sheet'!N5/'Balance Sheet'!N36 -> 0.20177517 | O29: 0.23 | P29: Borrowings/Total Asset | Q29: =AVERAGE(C29:N29) -> 0.35691218 | S29: Debt/Asset ratio has also followed the industrial average trend across the years, suggesting firm has not over-borrowed
C30: optimal | D30: optimal | E30: optimal | F30: optimal | G30: optimal | H30: optimal | I30: optimal | J30: optimal | K30: optimal | L30: optimal | M30: optimal | N30: optimal
B31: Interest Coverage Ratio | C31: ='Profit and Loss Statement'!C9/'Profit and Loss Statement'!C14 -> 1.8227474 | D31: ='Profit and Loss Statement'!D9/'Profit and Loss Statement'!D14 -> 2.9135977 | E31: ='Profit and Loss Statement'!E9/'Profit and Loss Statement'!E14 -> 2.6442652 | F31: ='Profit and Loss Statement'!F9/'Profit and Loss Statement'!F14 -> 2.330468 | G31: ='Profit and Loss Statement'!G9/'Profit and Loss Statement'!G14 -> 3.6666667 | H31: ='Profit and Loss Statement'!H9/'Profit and Loss Statement'!H14 -> 3.4304933 | I31: ='Profit and Loss Statement'!I9/'Profit and Loss Statement'!I14 -> 3.8553812 | J31: ='Profit and Loss Statement'!J9/'Profit and Loss Statement'!J14 -> 4.511822 | ... N31: ='Profit and Loss Statement'!N9/'Profit and Loss Statement'!N14 -> 4.9851259 | O31: 2.8 | P31: Operating Income/Interest expense | Q31: =AVERAGE(C31:N31) -> 3.9397718 | S31: Interest Coverage ratio has shown an increasing trend across the years, reflecting that a large portion of operating profit is used in the interest expense
C32: Good | D32: Good | E32: Good | F32: Good | G32: Good | H32: Good | I32: Excellent | J32: Excellent | K32: Excellent | L32: Excellent | M32: Excellent | N32: Excellent
B33: Equity to Asset Ratio | C33: ='Balance Sheet'!C3/'Balance Sheet'!C36 -> 0.030861776 | D33: ='Balance Sheet'!D3/'Balance Sheet'!D36 -> 0.029767911 | E33: ='Balance Sheet'!E3/'Balance Sheet'!E36 -> 0.024665402 | F33: ='Balance Sheet'!F3/'Balance Sheet'!F36 -> 0.023332525 | G33: ='Balance Sheet'!G3/'Balance Sheet'!G36 -> 0.021762736 | H33: ='Balance Sheet'!H3/'Balance Sheet'!H36 -> 0.020188877 | I33: ='Balance Sheet'!I3/'Balance Sheet'!I36 -> 0.021022727 | J33: ='Balance Sheet'!J3/'Balance Sheet'!J36 -> 0.021116867 | ... N33: ='Balance Sheet'!N3/'Balance Sheet'!N36 -> 0.015919644 | O33: 0.0286 | P33: Shareholders Equity/Total Asset | Q33: =AVERAGE(C33:N33) -> 0.022000144 | S33: Equity to Asset ratio has followed the industry average across the years(0.0286), consistent with the D/E ratio and D/A ratio
C34: Good | D34: Good | E34: Good | F34: Good | G34: Good | H34: Good | I34: Good | J34: Good | K34: Good | L34: Bad | M34: Bad | N34: Bad
B36: Turnover Ratios
B37: Inventory Turnover | C37: ='Profit and Loss Statement'!C3/'Balance Sheet'!C30 -> 30.162544 | D37: ='Profit and Loss Statement'!D3/'Balance Sheet'!D30 -> 40.316206 | E37: ='Profit and Loss Statement'!E3/'Balance Sheet'!E30 -> 27.680952 | F37: ='Profit and Loss Statement'!F3/'Balance Sheet'!F30 -> 26.886179 | G37: ='Profit and Loss Statement'!G3/'Balance Sheet'!G30 -> 25.218062 | H37: ='Profit and Loss Statement'!H3/'Balance Sheet'!H30 -> 20.698565 | I37: ='Profit and Loss Statement'!I3/'Balance Sheet'!I30 -> 22.478261 | J37: ='Profit and Loss Statement'!J3/'Balance Sheet'!J30 -> 30.510363 | ... N37: ='Profit and Loss Statement'!N3/'Balance Sheet'!N30 -> 35.981938 | O37: 2 | Q37: =AVERAGE(C37:N37) -> 29.274935 | S37: Inventory turnover is higher than the industry average ratio(2). Increasing trend observed across the years, suggesting that firm is efficiently utilizing its inventory
C38: Excellent | D38: Excellent | E38: Excellent | F38: Excellent | G38: Excellent | H38: Excellent | I38: Excellent | J38: Excellent | K38: Excellent | L38: Excellent | M38: Excellent | N38: Excellent
B39: Debtors Turnover | C39: ='Profit and Loss Statement'!C3/'Balance Sheet'!C35 -> 10.616915 | D39: ='Profit and Loss Statement'!D3/'Balance Sheet'!D35 -> 12.303981 | E39: ='Profit and Loss Statement'!E3/'Balance Sheet'!E35 -> 12.091524 | F39: ='Profit and Loss Statement'!F3/'Balance Sheet'!F35 -> 9.8325074 | G39: ='Profit and Loss Statement'!G3/'Balance Sheet'!G35 -> 10.940277 | H39: ='Profit and Loss Statement'!H3/'Balance Sheet'!H35 -> 11.309804 | I39: ='Profit and Loss Statement'!I3/'Balance Sheet'!I35 -> 11.430272 | J39: ='Profit and Loss Statement'!J3/'Balance Sheet'!J35 -> 9.5864876 | ... N39: ='Profit and Loss Statement'!N3/'Balance Sheet'!N35 -> 13.455941 | O39: 4.79 | P39: Sales/Average Receivables | Q39: =AVERAGE(C39:N39) -> 11.499155 | S39: Debtor's Turnover ratio is higher than the industry average(4.79) which suggests that firm is able to collect its revenue efficiently
C40: Excellent | D40: Excellent | E40: Excellent | F40: Excelllent | G40: Excellent | H40: Excellent | I40: Excellent | J40: Excellent | K40: Excellent | L40: Excellent | M40: Excellent | N40: Excellent
B41: Fixed Assets Turnover | C41: ='Profit and Loss Statement'!C3/'Balance Sheet'!C15 -> 0.91804689 | D41: ='Profit and Loss Statement'!D3/'Balance Sheet'!D15 -> 1.1208791 | E41: ='Profit and Loss Statement'!E3/'Balance Sheet'!E15 -> 0.77990206 | F41: ='Profit and Loss Statement'!F3/'Balance Sheet'!F15 -> 0.59768661 | G41: ='Profit and Loss Statement'!G3/'Balance Sheet'!G15 -> 0.68124479 | H41: ='Profit and Loss Statement'!H3/'Balance Sheet'!H15 -> 0.76287327 | I41: ='Profit and Loss Statement'!I3/'Balance Sheet'!I15 -> 0.85124438 | J41: ='Profit and Loss Statement'!J3/'Balance Sheet'!J15 -> 0.75580798 | ... N41: ='Profit and Loss Statement'!N3/'Balance Sheet'!N15 -> 1.396444 | O41: 0.2461 | P41: Sales/Fixed total asset | Q41: =AVERAGE(C41:N41) -> 0.94455978 | S41: Higher than the industry average of 0.2461, reflecting that fixed assets are used efficiently to generate revenue
C42: Good | D42: Excellent | E42: Good | F42: Good | G42: Good | H42: Good | I42: Good | J42: Good | K42: Good | L42: Excellent | M42: Excellent | N42: Excellent
B43: Total Assets Turnover | C43: ='Profit and Loss Statement'!C3/'Balance Sheet'!C37 -> 0.44630346 | D43: ='Profit and Loss Statement'!D3/'Balance Sheet'!D37 -> 0.65489567 | E43: ='Profit and Loss Statement'!E3/'Balance Sheet'!E37 -> 0.65763498 | F43: ='Profit and Loss Statement'!F3/'Balance Sheet'!F37 -> 0.49461561 | G43: ='Profit and Loss Statement'!G3/'Balance Sheet'!G37 -> 0.53603952 | H43: ='Profit and Loss Statement'!H3/'Balance Sheet'!H37 -> 0.56515775 | I43: ='Profit and Loss Statement'!I3/'Balance Sheet'!I37 -> 0.57561289 | J43: ='Profit and Loss Statement'!J3/'Balance Sheet'!J37 -> 0.51587893 | ... N43: ='Profit and Loss Statement'!N3/'Balance Sheet'!N37 -> 0.72023007 | O43: 0.17 | P43: Sales/Average Total Asset | Q43: =AVERAGE(C43:N43) -> 0.60339756 | S43: Higher than the industry average of 0.17, reflecting that assets are used efficiently to generate revenue, consistent with the efficient use of fixed assets
...

Sheet Du Pont 
B2: DU PONT ANALYSIS
B4: ROE - Dupont Equation
C5: 45369 | D5: 45370 | E5: 45371 | F5: 45372 | G5: 45373 | H5: 45374 | I5: 45375 | J5: 45376
B6: Net Profit | C6: ='Profit and Loss Statement'!G18 -> 922 | D6: ='Profit and Loss Statement'!H18 -> 889 | E6: ='Profit and Loss Statement'!I18 -> 1238 | F6: ='Profit and Loss Statement'!J18 -> 1325 | G6: ='Profit and Loss Statement'!K18 -> 410 | H6: ='Profit and Loss Statement'!L18 -> 2104 | I6: ='Profit and Loss Statement'!M18 -> 1798 | J6: ='Profit and Loss Statement'!N18 -> 2851
B7: Revenue | C7: ='Profit and Loss Statement'!G3 -> 11449 | D7: ='Profit and Loss Statement'!H3 -> 12978 | E7: ='Profit and Loss Statement'!I3 -> 13442 | F7: ='Profit and Loss Statement'!J3 -> 11777 | G7: ='Profit and Loss Statement'!K3 -> 13716 | H7: ='Profit and Loss Statement'!L3 -> 18836 | I7: ='Profit and Loss Statement'!M3 -> 19957 | J7: ='Profit and Loss Statement'!N3 -> 21913
B8: Net Profit Margin (A) | C8: =C6/C7 -> 0.080531051 | D8: =D6/D7 -> 0.068500539 | E8: =E6/E7 -> 0.09209939 | F8: =F6/F7 -> 0.11250743 | G8: =G6/G7 -> 0.029892097 | H8: =H6/H7 -> 0.111701 | I8: =I6/I7 -> 0.090093701 | J8: =J6/J7 -> 0.13010542
B10: Revenue | C10: =C7 -> 11449 | D10: =D7 -> 12978 | E10: =E7 -> 13442 | F10: =F7 -> 11777 | G10: =G7 -> 13716 | H10: =H7 -> 18836 | I10: =I7 -> 19957 | J10: =J7 -> 21913
B11: Average Total Asset | C11: ='Balance Sheet'!G36 -> 22102 | D11: ='Balance Sheet'!H36 -> 23825 | E11: ='Balance Sheet'!I36 -> 22880 | F11: ='Balance Sheet'!J36 -> 22778 | G11: ='Balance Sheet'!K36 -> 23605 | H11: ='Balance Sheet'!L36 -> 25988 | I11: ='Balance Sheet'!M36 -> 29191 | J11: ='Balance Sheet'!N36 -> 31659
B12: Asset Turnover Ratio (B) | C12: =C10/C11 -> 0.51800742 | D12: =D10/D11 -> 0.54472193 | E12: =E10/E11 -> 0.5875 | F12: =F10/F11 -> 0.51703398 | G12: =G10/G11 -> 0.58106333 | H12: =H10/H11 -> 0.72479606 | I12: =I10/I11 -> 0.68366962 | J12: =J10/J11 -> 0.69215705
B14: Average Total Asset | C14: =C11 -> 22102 | D14: =D11 -> 23825 | E14: =E11 -> 22880 | F14: =F11 -> 22778 | G14: =G11 -> 23605 | H14: =H11 -> 25988 | I14: =I11 -> 29191 | J14: =J11 -> 31659
B15: Average Shareholder Equity | C15: ='Balance Sheet'!G3+'Balance Sheet'!G4 -> 7693 | D15: ='Balance Sheet'!H3+'Balance Sheet'!H4 -> 8937 | E15: ='Balance Sheet'!I3+'Balance Sheet'!I4 -> 9188 | F15: ='Balance Sheet'!J3+'Balance Sheet'!J4 -> 10252 | G15: ='Balance Sheet'!K3+'Balance Sheet'!K4 -> 9966 | H15: ='Balance Sheet'!L3+'Balance Sheet'!L4 -> 11020 | I15: ='Balance Sheet'!M3+'Balance Sheet'!M4 -> 12039 | J15: ='Balance Sheet'!N3+'Balance Sheet'!N4 -> 17456
B16: Equity Multiplier (C) | C16: =C14/C15 -> 2.8730014 | D16: =D14/D15 -> 2.6658834 | E16: =E14/E15 -> 2.4902046 | F16: =F14/F15 -> 2.2218104 | G16: =G14/G15 -> 2.3685531 | H16: =H14/H15 -> 2.3582577 | I16: =I14/I15 -> 2.424703 | J16: =J14/J15 -> 1.8136457
B18: Return on Equity (A*B*C) | C18: =C8*C12*C16 -> 0.11984921 | D18: =D8*D12*D16 -> 0.099474096 | E18: =E8*E12*E16 -> 0.13474097 | F18: =F8*F12*F16 -> 0.12924307 | G18: =G8*G12*G16 -> 0.041139876 | H18: =H8*H12*H16 -> 0.19092559 | I18: =I8*I12*I16 -> 0.14934795 | J18: =J8*J12*J16 -> 0.16332493 | K18: This shows that the calculated Du Pont values are close to actual industry values
C19: 0.11984921 | D19: 0.099474096 | E19: 0.13474097 | F19: 0.12924307 | G19: 0.041139876 | H19: 0.19092559 | I19: 0.14934795 | J19: 0.16332493
B20: ROA - Dupont Equation
C21: 45369 | D21: 45370 | E21: 45371 | F21: 45372 | G21: 45373 | H21: 45374 | I21: 45375 | J21: 45376
B22: Net Profit | C22: =C6 -> 922 | D22: =D6 -> 889 | E22: =E6 -> 1238 | F22: =F6 -> 1325 | G22: =G6 -> 410 | H22: =H6 -> 2104 | I22: =I6 -> 1798 | J22: =J6 -> 2851
B23: Revenue | C23: =C7 -> 11449 | D23: =D7 -> 12978 | E23: =E7 -> 13442 | F23: =F7 -> 11777 | G23: =G7 -> 13716 | H23: =H7 -> 18836 | I23: =I7 -> 19957 | J23: =J7 -> 21913
B24: Net Profit Margin (A) | C24: =C8 -> 0.080531051 | D24: =D8 -> 0.068500539 | E24: =E8 -> 0.09209939 | F24: =F8 -> 0.11250743 | G24: =G8 -> 0.029892097 | H24: =H8 -> 0.111701 | I24: =I8 -> 0.090093701 | J24: =J8 -> 0.13010542
B26: Revenue | C26: =C10 -> 11449 | D26: =D10 -> 12978 | E26: =E10 -> 13442 | F26: =F10 -> 11777 | G26: =G10 -> 13716 | H26: =H10 -> 18836 | I26: =I10 -> 19957 | J26: =J10 -> 21913
B27: Average Total Asset | C27: =C11 -> 22102 | D27: =D11 -> 23825 | E27: =E11 -> 22880 | F27: =F11 -> 22778 | G27: =G11 -> 23605 | H27: =H11 -> 25988 | I27: =I11 -> 29191 | J27: =J11 -> 31659
B28: Asset Turnover Ratio (B) | C28: =C12 -> 0.51800742 | D28: =D12 -> 0.54472193 | E28: =E12 -> 0.5875 | F28: =F12 -> 0.51703398 | G28: =G12 -> 0.58106333 | H28: =H12 -> 0.72479606 | I28: =I12 -> 0.68366962 | J28: =J12 -> 0.69215705
B30: Return on Asset (A*B) | C30: =C24*C28 -> 0.041715682 | D30: =D24*D28 -> 0.037313746 | E30: =E24*E28 -> 0.054108392 | F30: =F24*F28 -> 0.058170164 | G30: =G24*G28 -> 0.017369201 | H30: =H24*H28 -> 0.080960443 | I30: =I24*I28 -> 0.061594327 | J30: =J24*J28 -> 0.090053381 | K30: This shows that the calculated Du Pont values are close to actual industry values
C31: 0.041715682 | D31: 0.037313746 | E31: 0.054108392 | F31: 0.0581 | G31: 0.0173 | H31: 0.0809 | I31: 0.0615 | J31: 0.09

Sheet Beta Calculation
AB1: Peers to Our companies
C2: NIFTY RETURNS | F2: TORRENT POWER | J2: Beta Drifting
B3: Date | C3: Price | D3: Change % | F3: Price | G3: Change % | Y3: NTPC | AB3: Power Grid Corporation of India | AE3: NHPC | AH3: Adani Green
B4: 45683 | C4: 23508.4 | D4: =(C4-C5)/C5 -> 0.018023402 | F4: 1463.45 | G4: =(F4-F5)/F5 -> -0.0042525686 | J4: Levered Raw beta | K4: =J18 -> 0.98885811 | Y4: Price | Z4: Change % | AB4: Price | AC4: Change % | AE4: Price | AF4: Change % | AH4: Price | AI4: Change %
B5: 45676 | C5: 23092.2 | D5: =(C5-C6)/C6 -> -0.0047838229 | F5: 1469.7 | G5: =(F5-F6)/F6 -> -0.0049424509 | J5: Raw Beta weight | K5: 0.75 | Z5: 0.0011 | AB5: 301.65 | AC5: 0.0196 | AE5: 80.55 | AF5: 0.0477 | AH5: 997.55 | AI5: -0.0144
B6: 45669 | C6: 23203.2 | D6: =(C6-C7)/C7 -> -0.0097432943 | F6: 1477 | G6: =(F6-F7)/F7 -> 0.087428677 | Y6: 323.65 | Z6: -0.0077 | AB6: 295.85 | AC6: -0.0223 | AE6: 76.88 | AF6: -0.0438 | AH6: 1012.1 | AI6: -0.0613
B7: 45662 | C7: 23431.5 | D7: =(C7-C8)/C8 -> -0.02388069 | F7: 1358.25 | G7: =(F7-F8)/F8 -> -0.10254716 | J7: Market Beta | K7: 1 | Y7: 326.15 | Z7: 0.0581 | AB7: 302.6 | AC7: 0.0097 | AE7: 80.4 | AF7: 0.0496 | AH7: 1078.2 | AI7: 0.1433
B8: 45655 | C8: 24004.75 | D8: =(C8-C9)/C9 -> 0.0080353918 | F8: 1513.45 | G8: =(F8-F9)/F9 -> 0.042715905 | J8: Market Beta weight | K8: =1-K5 -> 0.25 | Y8: 308.25 | Z8: -0.093 | AB8: 299.7 | AC8: -0.0517 | AE8: 76.6 | AF8: -0.0781 | AH8: 943.05 | AI8: -0.0917
B9: 45648 | C9: 23813.4 | D9: =(C9-C10)/C10 -> 0.0095771065 | F9: 1451.45 | G9: =(F9-F10)/F10 -> -0.018760141 | Y9: 339.85 | Z9: 0.0145 | AB9: 316.05 | AC9: 0.0215 | AE9: 83.09 | AF9: 0.0344 | AH9: 1038.25 | AI9: -0.0149
B10: 45641 | C10: 23587.5 | D10: =(C10-C11)/C11 -> -0.047673841 | F10: 1479.2 | G10: =(F10-F11)/F11 -> -0.11382698 | J10: Adj Beta for TORRENT POWER | K10: =K4*K5+K7*K8 -> 0.99164358 | Y10: 335 | Z10: 0.0053 | AB10: 309.4 | AC10: -0.0203 | AE10: 80.33 | AF10: -0.014 | AH10: 1054 | AI10: 0.019
B11: 45634 | C11: 24768.3 | D11: =(C11-C12)/C12 -> 0.0036672637 | F11: 1669.2 | G11: =(F11-F12)/F12 -> 0.012464744 | Y11: 333.25 | Z11: -0.0669 | AB11: 315.8 | AC11: -0.0541 | AE11: 81.47 | AF11: -0.0465 | AH11: 1034.35 | AI11: -0.1369
B12: 45627 | C12: 24677.8 | D12: =(C12-C13)/C13 -> 0.022655411 | F12: 1648.65 | G12: =(F12-F13)/F13 -> 0.091315284 | Y12: 357.15 | Z12: -0.0334 | AB12: 333.85 | AC12: 0.0151 | AE12: 85.44 | AF12: 0.0067 | AH12: 1198.4 | AI12: -0.0101
B13: 45620 | C13: 24131.1 | D13: =(C13-C14)/C14 -> 0.0093632685 | F13: 1510.7 | G13: =(F13-F14)/F14 -> -0.0044154475 | Y13: 369.5 | Z13: 0.0161 | AB13: 328.9 | AC13: -0.0015 | AE13: 84.87 | AF13: 0.0421 | AH13: 1210.65 | AI13: -0.0855
B14: 45613 | C14: 23907.25 | D14: =(C14-C15)/C15 -> 0.015916151 | F14: 1517.4 | G14: =(F14-F15)/F15 -> -0.026683772 | T14: Peers Beta using Historical data | Y14: 363.65 | Z14: -0.0049 | AB14: 329.4 | AC14: -0.0224 | AE14: 81.44 | AF14: 0.0288 | AH14: 1323.9 | AI14: 0.2587
B15: 45606 | C15: 23532.7 | D15: =(C15-C16)/C16 -> -0.025488442 | F15: 1559 | G15: =(F15-F16)/F16 -> -0.079747358 | T15: Beta NTPC | U15: =SLOPE(Z5:Z212,D4:D211) -> 0.77953235 | Y15: 365.45 | Z15: -0.0189 | AB15: 336.95 | AC15: 0.0796 | AE15: 79.16 | AF15: 0.01 | AH15: 1051.8 | AI15: -0.2942
B16: 45599 | C16: 24148.2 | D16: =(C16-C17)/C17 -> -0.0064247758 | F16: 1694.1 | G16: =(F16-F17)/F17 -> -0.07195486 | I16: Beta 1 TORRENT POWER | J16: =SLOPE(G4:G211,D4:D211) -> 0.98893426 | T16: Beta Power Grid | U16: =SLOPE(AC5:AC212,D4:D211) -> 0.49201002 | Y16: 372.5 | Z16: -0.0632 | AB16: 312.1 | AC16: -0.0131 | AE16: 78.38 | AF16: -0.0482 | AH16: 1490.3 | AI16: -0.0677
B17: 45592 | C17: 24304.35 | D17: =(C17-C18)/C18 -> 0.0051094257 | F17: 1825.45 | G17: =(F17-F18)/F18 -> -0.051122778 | I17: Beta 2 TORRENT POWER | J17: {=_xlfn.COVARIANCE.S(D4:D211,G4:G211/_xlfn.VAR.S(D4:D211))} -> 0.98893426 | T17: Beta NHPC Energy | U17: =SLOPE(AF5:AF212,D4:D211) -> 0.82949626 | Y17: 397.65 | Z17: -0.0333 | AB17: 316.25 | AC17: -0.018 | AE17: 82.35 | AF17: -0.0212 | AH17: 1598.55 | AI17: -0.0209
B18: 45585 | C18: 24180.8 | D18: =(C18-C19)/C19 -> -0.027088141 | F18: 1923.8 | G18: =(F18-F19)/F19 -> -0.025257771 | I18: Beta 3 TORRENT POWER | J18: =J41 -> 0.98885811 | T18: Beta Adani green | U18: =SLOPE(AI5:AI212,D4:D211) -> 1.0655616 | Y18: 411.35 | Z18: 0.0312 | AB18: 322.05 | AC18: 0.0198 | AE18: 84.13 | AF18: 0.0717 | AH18: 1632.65 | AI18: -0.0069
B19: 45578 | C19: 24854.05 | D19: =(C19-C20)/C20 -> -0.0044143125 | F19: 1973.65 | G19: =(F19-F20)/F20 -> 0.04625212 | Y19: 398.9 | Z19: -0.0613 | AB19: 315.8 | AC19: -0.0489 | AE19: 78.5 | AF19: -0.0669 | AH19: 1644 | AI19: -0.053
B20: 45571 | C20: 24964.25 | D20: =(C20-C21)/C21 -> -0.0020128245 | F20: 1886.4 | G20: =(F20-F21)/F21 -> -0.0022742899 | Y20: 424.95 | Z20: 0.0058 | AB20: 332.05 | AC20: 0.0061 | AE20: 84.13 | AF20: -0.0747 | AH20: 1736.05 | AI20: -0.0313
B21: 45564 | C21: 25014.6 | D21: =(C21-C22)/C22 -> -0.044476574 | F21: 1890.7 | G21: =(F21-F22)/F22 -> -0.0089632037 | Y21: 422.5 | Z21: -0.0185 | AB21: 330.05 | AC21: -0.026 | AE21: 90.92 | AF21: -0.0241 | AH21: 1792.2 | AI21: -0.005
B22: 45557 | C22: 26178.95 | D22: =(C22-C23)/C23 -> 0.015044037 | F22: 1907.8 | G22: =(F22-F23)/F23 -> 0.0030230541 | Y22: 430.45 | Z22: -0.0148 | AB22: 338.85 | AC22: -0.0435 | AE22: 93.17 | AF22: -0.0228 | AH22: 1801.2 | AI22: -0.0912
B23: 45550 | C23: 25790.95 | D23: =(C23-C24)/C24 -> 0.017133674 | F23: 1902.05 | G23: =(F23-F24)/F24 -> 0.078871242 | Y23: 436.9 | Z23: 0.0305 | AB23: 354.25 | AC23: 0.0393 | AE23: 95.34 | AF23: 0.0073 | AH23: 1981.85 | AI23: -0.011
B24: 45543 | C24: 25356.5 | D24: =(C24-C25)/C25 -> 0.020294019 | F24: 1763 | G24: =(F24-F25)/F25 -> 0.040210048 | I24: SUMMARY OUTPUT | Y24: 423.95 | Z24: 0.0562 | AB24: 340.85 | AC24: 0.0107 | AE24: 94.65 | AF24: 0.0039 | AH24: 2003.95 | AI24: 0.1207
B25: 45536 | C25: 24852.15 | D25: =(C25-C26)/C26 -> -0.015206511 | F25: 1694.85 | G25: =(F25-F26)/F26 -> -0.027903642 | Y25: 401.4 | Z25: 0.0167 | AB25: 337.25 | AC25: 0.0226 | AE25: 94.28 | AF25: -0.0188 | AH25: 1788.2 | AI25: -0.0403
B26: 45529 | C26: 25235.9 | D26: =(C26-C27)/C27 -> 0.016627624 | F26: 1743.5 | G26: =(F26-F27)/F27 -> 0.042763158 | I26: Regression Statistics | Y26: 394.8 | Z26: -0.0514 | AB26: 329.8 | AC26: -0.0225 | AE26: 96.09 | AF26: -0.0003 | AH26: 1863.3 | AI26: 0.0137
B27: 45522 | C27: 24823.15 | D27: =(C27-C28)/C28 -> 0.011490904 | F27: 1672 | G27: =(F27-F28)/F28 -> -0.0095373497 | I27: Multiple R | J27: 0.36421924 | Y27: 416.2 | Z27: 0.0355 | AB27: 337.4 | AC27: 0.0034 | AE27: 96.12 | AF27: -0.01 | AH27: 1838.15 | AI27: -0.033
B28: 45515 | C28: 24541.15 | D28: =(C28-C29)/C29 -> 0.0071262953 | F28: 1688.1 | G28: =(F28-F29)/F29 -> -0.057716997 | I28: R Square | J28: 0.13265565 | Y28: 401.95 | Z28: 0.0098 | AB28: 336.25 | AC28: -0.0069 | AE28: 97.09 | AF28: 0.0314 | AH28: 1900.9 | AI28: 0.0382
B29: 45508 | C29: 24367.5 | D29: =(C29-C30)/C30 -> -0.014167985 | F29: 1791.5 | G29: =(F29-F30)/F30 -> -0.032327761 | I29: Adjusted R Square | J29: 0.12844524 | Y29: 398.05 | Z29: -0.0307 | AB29: 338.6 | AC29: -0.0214 | AE29: 94.13 | AF29: -0.0372 | AH29: 1831 | AI29: 0.0282
B30: 45501 | C30: 24717.7 | D30: =(C30-C31)/C31 -> -0.0047171616 | F30: 1851.35 | G30: =(F30-F31)/F31 -> 0.18916402 | I30: Standard Error | J30: 0.04601342 | Y30: 410.65 | Z30: -0.0216 | AB30: 346 | AC30: -0.0342 | AE30: 97.77 | AF30: -0.0536 | AH30: 1780.85 | AI30: -0.0534
B31: 45494 | C31: 24834.85 | D31: =(C31-C32)/C32 -> 0.012390495 | F31: 1556.85 | G31: =(F31-F32)/F32 -> 0.019882083 | I31: Observations | J31: 208 | Y31: 419.7 | Z31: 0.059 | AB31: 358.25 | AC31: 0.0408 | AE31: 103.31 | AF31: -0.0125 | AH31: 1881.4 | AI31: 0.0431
B32: 45487 | C32: 24530.9 | D32: =(C32-C33)/C33 -> 0.0011733664 | F32: 1526.5 | G32: =(F32-F33)/F33 -> 0.010893679 | Y32: 396.3 | Z32: 0.0868 | AB32: 344.2 | AC32: 0.0361 | AE32: 104.62 | AF32: -0.0155 | AH32: 1803.7 | AI32: 0.0467
B33: 45480 | C33: 24502.15 | D33: =(C33-C34)/C34 -> 0.0073302541 | F33: 1510.05 | G33: =(F33-F34)/F34 -> 0.00036435906 | I33: ANOVA | Y33: 364.65 | Z33: -0.0331 | AB33: 332.2 | AC33: -0.0318 | AE33: 106.27 | AF33: -0.0597 | AH33: 1723.3 | AI33: -0.0069
B34: 45473 | C34: 24323.85 | D34: =(C34-C35)/C35 -> 0.013046321 | F34: 1509.5 | G34: =(F34-F35)/F35 -> 0.0074079018 | J34: df | K34: SS | L34: MS | M34: F | N34: Significance F | Y34: 377.15 | Z34: -0.007 | AB34: 343.1 | AC34: 0.0109 | AE34: 113.02 | AF34: 0.0886 | AH34: 1735.25 | AI34: -0.0109
B35: 45466 | C35: 24010.6 | D35: =(C35-C36)/C36 -> 0.021679836 | F35: 1498.4 | G35: =(F35-F36)/F36 -> -0.0033589411 | I35: Regression | J35: 1 | K35: 0.06670686 | L35: 0.06670686 | M35: 31.506592 | N35: 6.3697e-08 | Y35: 379.8 | Z35: 0.0038 | AB35: 339.4 | AC35: 0.0255 | AE35: 103.82 | AF35: 0.031 | AH35: 1754.3 | AI35: -0.0193
B36: 45459 | C36: 23501.1 | D36: =(C36-C37)/C37 -> 0.0015128529 | F36: 1503.45 | G36: =(F36-F37)/F37 -> -0.059814896 | I36: Residual | J36: 206 | K36: 0.43615043 | L36: 0.00211724 | Y36: 378.35 | Z36: 0.0516 | AB36: 330.95 | AC36: 0.0153 | AE36: 100.7 | AF36: -0.0006 | AH36: 1788.8 | AI36: 0.0047
B37: 45452 | C37: 23465.6 | D37: =(C37-C38)/C38 -> 0.0075332276 | F37: 1599.1 | G37: =(F37-F38)/F38 -> 0.067489987 | I37: Total | J37: 207 | K37: 0.50285729 | Y37: 359.8 | Z37: -0.0235 | AB37: 325.95 | AC37: 0.0138 | AE37: 100.76 | AF37: -0.0178 | AH37: 1780.45 | AI37: -0.0143
B38: 45445 | C38: 23290.15 | D38: =(C38-C39)/C39 -> 0.033707342 | F38: 1498 | G38: =(F38-F39)/F39 -> -0.002530297 | Y38: 368.45 | Z38: 0.0218 | AB38: 321.5 | AC38: 0.0393 | AE38: 102.59 | AF38: -0.0059 | AH38: 1806.3 | AI38: -0.0311
B39: 45438 | C39: 22530.7 | D39: =(C39-C40)/C40 -> -0.018573775 | F39: 1501.8 | G39: =(F39-F40)/F40 -> 0.072254748 | J39: Coefficients | K39: Standard Error | L39: t Stat | M39: P-value | N39: Lower 95% | O39: Upper 95% | P39: Lower 95.0% | Q39: Upper 95.0% | Y39: 360.6 | Z39: 0.0045 | AB39: 309.35 | AC39: -0.0021 | AE39: 103.2 | AF39: -0.0378 | AH39: 1864.25 | AI39: -0.0231
B40: 45431 | C40: 22957.1 | D40: =(C40-C41)/C41 -> 0.021855151 | F40: 1400.6 | G40: =(F40-F41)/F41 -> 0.015921372 | I40: Intercept | J40: 0.00634828 | K40: 0.00321717 | L40: 1.9732489 | M40: 0.04980436 | N40: 5.4763e-06 | O40: 0.01269109 | P40: 5.4763e-06 | Q40: 0.01269109 | Y40: 359 | Z40: -0.0425 | AB40: 310 | AC40: -0.0276 | AE40: 107.25 | AF40: 0.0469 | AH40: 1908.35 | AI40: -0.0095
...

Sheet Market return
B2: Returns on Market
B4: Year | C4: Annual
B5: 2000 | C5: -0.1465
B6: 2001 | C6: -0.1618
B7: 2002 | C7: 0.0325 | E7: Average Return | G7: =AVERAGE(C5:C29) -> 0.153348
B8: 2003 | C8: 0.719 | E8: Dividend Yield | G8: 0.0129
B9: 2004 | C9: 0.1068 | E9: Total Market return | G9: =SUM(G7:G8) -> 0.166248
B10: 2005 | C10: 0.3634
B11: 2006 | C11: 0.3983
B12: 2007 | C12: 0.5477
B13: 2008 | C13: -0.5179
B14: 2009 | C14: 0.7576
B15: 2010 | C15: 0.1795
B16: 2011 | C16: -0.2462
B17: 2012 | C17: 0.277
B18: 2013 | C18: 0.0676
B19: 2014 | C19: 0.3139
B20: 2015 | C20: -0.0406
B21: 2016 | C21: 0.0301
... B29: 2024 | C29: 0.0875

Sheet Peer Comparison & COE
A1: This sheet does a peer comparison of Torrent Power and power sector firms on basis of their (Debt to equity ratio) , and later using that and levered and unlevered beta by bottom Up approach, we have calculated the Required Returns or Cost of equity (Ke by CAPM model)
B5: Peer Comparison
B7: Name | C7: Total debt | D7: Total Equity | E7: Tax Rate | F7: Debt/. Equity | G7: Debt/. Capital | H7: Levered Beta | I7: Unlevered Beta
B9: Torrent Power | C9: 8775 | D9: 72637 | E9: 0.3 | F9: =C9/D9 -> 0.1208062 | G9: =C9/(C9+D9) -> 0.10778509 | H9: ='Beta Calculation'!K4 -> 0.98885811 | I9: =H9/(1+(1-E9)*F9) -> 0.91175606
B10: NTPC | C10: 250096.15 | D10: 328038.22 | E10: 0.3 | F10: =C10/D10 -> 0.76239942 | G10: =C10/(C10+D10) -> 0.43259173 | H10: ='Beta Calculation'!U15 -> 0.77953235 | I10: =H10/(1+(1-E10)*F10) -> 0.50827588
B11: Power Grid corp | C11: 131030.21 | D11: 278320.57 | E11: 0.3 | F11: =C11/D11 -> 0.47078881 | G11: =C11/(C11+D11) -> 0.32009273 | H11: ='Beta Calculation'!U16 -> 0.49201002 | I11: =H11/(1+(1-E11)*F11) -> 0.37005695
B12: Adani Green | C12: 80040 | D12: 164790.87 | E12: 0.3 | F12: =C12/D12 -> 0.48570652 | G12: =C12/(C12+D12) -> 0.32691956 | H12: ='Beta Calculation'!U18 -> 1.0655616 | I12: =H12/(1+(1-E12)*F12) -> 0.79519843
B13: NHPC Ltd | C13: 39556.78 | D13: 85935.27 | E13: 0.3 | F13: =C13/D13 -> 0.46030902 | G13: =C13/(C13+D13) -> 0.31521343 | H13: ='Beta Calculation'!U17 -> 0.82949626 | I13: =H13/(1+(1-E13)*F13) -> 0.62735291
D15: Average | E15: =AVERAGE(E9:E13) -> 0.3 | F15: =AVERAGE(F9:F13) -> 0.460002 | G15: =AVERAGE(G9:G13) -> 0.30052051 | H15: =AVERAGE(H9:H13) -> 0.83109166 | I15: =AVERAGE(I9:I13) -> 0.64252805
D16: Median | E16: =MEDIAN(E9:E13) -> 0.3 | F16: =MEDIAN(F9:F13) -> 0.47078881 | G16: =MEDIAN(G9:G13) -> 0.32009273 | H16: =MEDIAN(H9:H13) -> 0.82949626 | I16: =MEDIAN(I9:I13) -> 0.62735291
D17: *Tax rate is take as 30% which is market standard
E23: Current | H23: Companies average beta (unlevered) | J23: =I15 -> 0.64252805
C24: Total Debt | D24: 8775 | E24: =D24/D26 -> 0.10778509 | H24: Current debt/equity | J24: =E28 -> 0.1208062
C25: Market Cap | D25: 72637 | E25: =D25/D26 -> 0.89221491 | H25: Tax rate | J25: =E15 -> 0.3
C26: Total Cap | D26: =D24+D25 -> 81412 | E26: =E24+E25 -> 1 | H26: Levered Beta | J26: =J23*(1+(1-E15)*J24) -> 0.69686301
C28: Debt/Equity | E28: =E24/E25 -> 0.1208062 | H28: Risk free rate | J28: 0.06316
H29: Market return (NIFTY 50 : 25 years) | J29: 0.166248
H30: Equity Risk premium | J30: =J29-J28 -> 0.103088
H31: Ke | J31: =J28+J30*J26 -> 0.13499821
H32: Formula used for calculation (CAPM model) -> Ke = [rf+ (rm-rf)*beta]

Sheet COD
B1: This is a table that relates the interest coverage ratio of a firm to a "synthetic" rating and a default spread that goes with that rating. The link between interest coverage ratios and ratings was developed by looking at all rated companies in the United States. The default spreads are obtained from traded bonds. Adding that number to a riskfree rate should yield the pre-tax cost of borrowing for a firm.
B6: Date of Analysis: Data used is as of January 2025
B8: For large non-financial service firms | G8: For financial service firms (default spreads are slighty different)
B9: If interest coverage ratio is | G9: If long term interest coverage ratio is | M9: *Since this synthetic ratings are US based we are adjusting the default spread for India
B10: > | C10: ≤ to | D10: Rating is | E10: Spread is | G10: greater than | H10: ≤ to | I10: Rating is | J10: Spread is | M10: USA | N10: 0 | O10: 0.0433 | P10: 0 | Q10: 0.25
B11: -100000 | C11: 0.199999 | D11: D2/D | E11: 0.19 | G11: -100000 | H11: 0.049999 | I11: D2/D | J11: 0.19 | M11: India | N11: 0.0218 | O11: 0.0726 | P11: 0.0293 | Q11: 0.3
B12: 0.2 | C12: 0.649999 | D12: C2/C | E12: 0.155 | G12: 0.05 | H12: 0.099999 | I12: C2/C | J12: 0.155 | M12: Adj. Default Spread | O12: Equity Risk Premium | P12: Country Risk Premium | Q12: Corporate Tax Rate
B13: 0.65 | C13: 0.799999 | D13: Ca2/CC | E13: 0.101 | G13: 0.1 | H13: 0.199999 | I13: Ca2/CC | J13: 0.101
B14: 0.8 | C14: 1.249999 | D14: Caa/CCC | E14: 0.0728 | G14: 0.2 | H14: 0.299999 | I14: Caa/CCC | J14: 0.0728
B15: 1.25 | C15: 1.499999 | D15: B3/B- | E15: 0.0442 | G15: 0.3 | H15: 0.399999 | I15: B3/B- | J15: 0.0442 | L15: 1) | M15: Torrent Power rating | N15: A+ | O15: ='Peer Comparison & COE'!J28+COD!E23+COD!N11 -> 0.09266 | P15: kd = RFR (India) + Default spread of the BA rated bond (India)
B16: 1.5 | C16: 1.749999 | D16: B2/B | E16: 0.03 | G16: 0.4 | H16: 0.499999 | I16: B2/B | J16: 0.03 | M16: (Crisil)
B17: 1.75 | C17: 1.999999 | D17: B1/B+ | E17: 0.0261 | G17: 0.5 | H17: 0.599999 | I17: B1/B+ | J17: 0.0261 | L17: 2) | M17: Formula Used | O17: =('Profit and Loss Statement'!N14/'Balance Sheet'!N5)*100 -> 13.681904 | P17: Kd = interest expenses/ (interest bearing debt)
B18: 2 | C18: 2.2499999 | D18: Ba2/BB | E18: 0.0183 | G18: 0.6 | H18: 0.749999 | I18: Ba2/BB | J18: 0.0183
B19: 2.25 | C19: 2.49999 | D19: Ba1/BB+ | E19: 0.0155 | G19: 0.75 | H19: 0.899999 | I19: Ba1/BB+ | J19: 0.0155 | N19: Cost of debt after tax | O19: =O15*(1-0.3) -> 0.064862
B20: 2.5 | C20: 2.999999 | D20: Baa2/BBB | E20: 0.012 | G20: 0.9 | H20: 1.199999 | I20: Baa2/BBB | J20: 0.012
B21: 3 | C21: 4.249999 | D21: A3/A- | E21: 0.0095 | G21: 1.2 | H21: 1.49999 | I21: A3/A- | J21: 0.0095
B22: 4.25 | C22: 5.499999 | D22: A2/A | E22: 0.0085 | G22: 1.5 | H22: 1.99999 | I22: A2/A | J22: 0.0085
B23: 5.5 | C23: 6.499999 | D23: A1/A+ | E23: 0.0077 | G23: 2 | H23: 2.49999 | I23: A1/A+ | J23: 0.0077
B24: 6.5 | C24: 8.499999 | D24: Aa2/AA | E24: 0.006 | G24: 2.5 | H24: 2.99999 | I24: Aa2/AA | J24: 0.006
B25: 8.5 | C25: 100000 | D25: Aaa/AAA | E25: 0.0045 | G25: 3 | H25: 100000 | I25: Aaa/AAA | J25: 0.0045
B27: For smaller and riskier non-financial service firms
B28: If interest coverage ratio is
B29: greater than | C29: ≤ to | D29: Rating is | E29: Spread is
B30: -100000 | C30: 0.499999 | D30: D2/D | E30: 0.19
B31: 0.5 | C31: 0.799999 | D31: C2/C | E31: 0.155
B32: 0.8 | C32: 1.249999 | D32: Ca2/CC | E32: 0.101
B33: 1.25 | C33: 1.499999 | D33: Caa/CCC | E33: 0.0728
B34: 1.5 | C34: 1.999999 | D34: B3/B- | E34: 0.0442
B35: 2 | C35: 2.499999 | D35: B2/B | E35: 0.03
B36: 2.5 | C36: 2.999999 | D36: B1/B+ | E36: 0.0261
B37: 3 | C37: 3.499999 | D37: Ba2/BB | E37: 0.0183
B38: 3.5 | C38: 3.9999999 | D38: Ba1/BB+ | E38: 0.0155
B39: 4 | C39: 4.499999 | D39: Baa2/BBB | E39: 0.012
B40: 4.5 | C40: 5.999999 | D40: A3/A- | E40: 0.0095
B41: 6 | C41: 7.499999 | D41: A2/A | E41: 0.0085
... B44: 12.5 | C44: 100000 | D44: Aaa/AAA | E44: 0.0045

Sheet WACC
A1: WACC
A3: Wt. of debt | B3: ='Peer Comparison & COE'!E24 -> 0.10778509
A4: Cost of debt(pre-tax) | B4: =COD!O15 -> 0.09266
A5: Cost of debt @30 TAX | B5: =COD!O19 -> 0.064862
A6: Calculating using synthetic rating adjusted to indian economy
A9: Wt of Equity | B9: ='Peer Comparison & COE'!E25 -> 0.89221491
A10: Cost of Equity | B10: ='Peer Comparison & COE'!J31 -> 0.13499821
A11: Calculated using CAPM model
A12: WACC | B12: =B10*B9+B5*B3 -> 0.12743858

Sheet Data_sheet for growth
C2: Mar-14 | D2: Mar-15 | E2: Mar-16 | F2: Mar-17 | G2: Mar-18 | H2: Mar-19 | I2: Mar-20 | J2: Mar-21 | K2: Mar-22 | L2: Mar-23 | M2: Mar-24 | N2: Mar-25
B3: Equity Capital | C3: 472 | D3: 472 | E3: 481 | F3: 481 | G3: 481 | H3: 481 | I3: 481 | J3: 481 | K3: 481 | L3: 481 | M3: 481 | N3: 504
B4: Reserves | C4: 5704 | D4: 6436 | E4: 5978 | F4: 6404 | G4: 7212 | H4: 8456 | I4: 8707 | J4: 9771 | K4: 9485 | L4: 10539 | M4: 11558 | N4: 16952
B5: Borrowings - | C5: 6149 | D5: 5629 | E5: 8392 | F5: 8666 | G5: 9216 | H5: 9116 | I5: 8340 | J5: 7200 | K5: 7908 | L5: 8430 | M5: 9744 | N5: 6388
B6: Long term Borrowings | C6: 5594 | D6: 5019 | E6: 8096 | F6: 8112 | G6: 8502 | H6: 8033 | I6: 7296 | J6: 6071 | K6: 6120 | L6: 7045 | M6: 8285 | N6: 5236
B7: Short term Borrowings | C7: 0 | D7: 0 | E7: 0 | F7: 77 | G7: 0 | H7: 300 | I7: 0 | J7: 1093 | K7: 1746 | L7: 1345 | M7: 1418 | N7: 1119
B8: Lease Liabilities | C8: 0 | D8: 0 | E8: 0 | F8: 0 | G8: 0 | H8: 0 | I8: 38 | J8: 36 | K8: 42 | L8: 41 | M8: 41 | N8: 32
B9: Other Borrowings | C9: 555 | D9: 610 | E9: 296 | F9: 478 | G9: 714 | H9: 783 | I9: 1006 | J9: 0 | K9: 0 | L9: 0 | M9: 0 | N9: 0
B10: Other Liabilities - | C10: 2969 | D10: 3318 | E10: 4650 | F10: 5064 | G10: 5193 | H10: 5772 | I10: 5352 | J10: 5327 | K10: 5730 | L10: 6538 | M10: 7409 | N10: 7815
B11: Trade Payables | C11: 633 | D11: 621 | E11: 735 | F11: 733 | G11: 657 | H11: 804 | I11: 1027 | J11: 971 | K11: 1108 | L11: 1081 | M11: 1090 | N11: 1370
B12: Advance from Customers | C12: 58 | D12: 72 | E12: 68 | F12: 63 | G12: 59 | H12: 67 | I12: 82 | J12: 84 | K12: 99 | L12: 94 | M12: 97 | N12: 97
B13: Other liability items | C13: 2277 | D13: 2625 | E13: 3847 | F13: 4268 | G13: 4477 | H13: 4901 | I13: 4243 | J13: 4271 | K13: 4523 | L13: 5363 | M13: 6221 | N13: 6445
B14: Total Liabilities | C14: 15294 | D14: 15856 | E14: 19501 | F14: 20615 | G14: 22102 | H14: 23825 | I14: 22880 | J14: 22778 | K14: 23605 | L14: 25988 | M14: 29191 | N14: 31659
... B27: Accumulated Depreciation | C27: 2802.63 | D27: 3335.6 | E27: 900.12 | F27: 1889.67 | G27: 2993.03 | H27: 4146.06 | I27: 6363.97 | J27: 7496.25 | K27: 9995.62 | L27: 11017.85 | M27: 12093.27 | N27: 12093.27
B28: NET BLOCK | C28: =C26-C29 -> 12100.54 | D28: =D26-D29 -> 12436.1 | E28: =E26-E29 -> 15807.61 | F28: =F26-F29 -> 18488.67 | G28: =G26-G29 -> 19798.82 | H28: =H26-H29 -> 21158.5 | I28: =I26-I29 -> 22154.82 | J28: =J26-J29 -> 23078.14 | ... N28: =N26-N29 -> 28236.42
B30: CWIP | C30: 118 | D30: 166 | E30: 204 | F30: 323 | G30: 393 | H30: 359 | I30: 568 | J30: 838 | K30: 1186 | L30: 1609 | M30: 816 | N30: 756
B31: Investments | C31: 2612 | D31: 2658 | E31: 695 | F31: 754 | G31: 989 | H31: 1162 | I31: 1021 | J31: 781 | K31: 1414 | L31: 2494 | M31: 2742 | N31: 2416
B33: Other Assets - | C33: 3266 | D33: 3932 | E33: 3694 | F33: 2939 | G33: 3915 | H33: 5291 | I33: 5500 | J33: 5578 | K33: 6697 | L33: 7119 | M33: 9490 | N33: 12795
B34: Inventories | C34: 283 | D34: 253 | E34: 420 | F34: 369 | G34: 454 | H34: 627 | I34: 598 | J34: 386 | K34: 438 | L34: 646 | M34: 646 | N34: 609
B35: Trade receivables | C35: 784 | D35: 874 | E35: 1049 | F35: 969 | G35: 1124 | H35: 1171 | I35: 1181 | J35: 1276 | K35: 1364 | L35: 1516 | M35: 1566 | N35: 1691
B36: Cash Equivalents | C36: 1527 | D36: 1580 | E36: 778 | F36: 269 | G36: 270 | H36: 326 | I36: 224 | J36: 189 | K36: 207 | L36: 282 | M36: 311 | N36: 297
B37: Loans n Advances | C37: 70 | D37: 611 | E37: 215 | F37: 103 | G37: 685 | H37: 255 | I37: 181 | J37: 181 | K37: 1146 | L37: 219 | M37: 408 | N37: 5783
B38: Other asset items | C38: 603 | D38: 613 | E38: 1232 | F38: 1230 | G38: 1382 | H38: 2913 | I38: 3316 | J38: 3546 | K38: 3542 | L38: 4457 | M38: 6559 | N38: 4415
